<?xml version="1.0"?>
<robot name="Humanoid">
    <link name="root">
		
	</link>

    <link name="assist_link1">
        
    </link>

    <joint name="0" type="fixed">
        <origin xyz="0 0 0" rpy="0.0 0.0 0.0"/>
        <parent link="root"/>
        <child link="assist_link1"/>
        <axis xyz="0.0 0.0 0.0"/>
        <limit lower="0.0" upper="0.0" effort="0.0" velocity="0.0"/>
    </joint>

    <joint name="assist_jointA1" type="fixed">
        <origin xyz="0.0 0.0 0.0" rpy="0.0 0.0 0.0"/>
        <parent link="assist_link1"/>
        <child link="hip"/>
        <axis xyz="0.0 0.0 0.0"/>
        <limit lower="0.0" upper="0.0" effort="0.0" velocity="0.0"/>
    </joint>

    <link name="hip">
        <inertial>
            <origin xyz="0.00057561 -0.00681268 -0.01696218" rpy="0.0 0.0 0.0"/>
            <mass value="0.0"/>
            <inertia ixx="0.0" ixy="0.0" ixz="0.0" iyy="0.0" iyz="0.0" izz="0.0"/>
        </inertial>
        <visual>
            <origin xyz="0.00057561 -0.00681268 -0.01696218" rpy="0.0 0.0 0.0"/>
            <geometry>
                <mesh filename="package://Humanoid/meshes/body_parts_hips.obj" />
            </geometry>
        </visual>
        <collision>
            <origin xyz="0.00057561 -0.00681268 -0.01696218" rpy="0.0 0.0 0.0"/>
            <geometry>
                <mesh filename="package://Humanoid/meshes/body_parts_hips.obj" />
            </geometry>
        </collision>
    </link>

    <joint name="assist_jointA2" type="fixed">
        <origin xyz="0.0 0.0 0.0" rpy="0.0 0.0 0.0"/>
        <parent link="assist_link1"/>
        <child link="temp1"/>
        <axis xyz="0.0 0.0 0.0"/>
        <limit lower="0.0" upper="0.0" effort="0.0" velocity="0.0"/>
    </joint>

    <link name="temp2">
        
    </link>

    <link name="left_UpLeg">
        <inertial>
            <origin xyz="0.02136212 -0.15149257 0.00267958" rpy="0.0 0.0 0.0"/>
            <mass value="0.0"/>
            <inertia ixx="0.0" ixy="0.0" ixz="0.0" iyy="0.0" iyz="0.0" izz="0.0"/>
        </inertial>
        <visual>
            <origin xyz="0.02136212  -0.15149257  0.00267958" rpy="0.0 0.0 0.0"/>
            <geometry>
                <mesh filename="package://Humanoid/meshes/body_parts_leftUpLeg.obj" />
            </geometry>
        </visual>
        <collision>
            <origin xyz="0.02136212 -0.15149257 0.00267958" rpy="0.0 0.0 0.0"/>
            <geometry>
                <mesh filename="package://Humanoid/meshes/body_parts_leftUpLeg.obj" />
            </geometry>
        </collision>
    </link>

    <joint name="2" type="revolute">
        <origin xyz="0.06951974 -0.09140623 -0.00681533" rpy="0.0 0.0 0.0"/>
        <parent link="temp2"/>
        <child link="left_UpLeg"/>
        <axis xyz="1.0 0.0 0.0"/>
        <limit lower="-2.5" upper="1.4" effort="1000.0" velocity="0.5"/>
    </joint>

    <link name="temp1">
        
    </link>

    <joint name="assist_jointA3" type="fixed">
        <origin xyz="0.0 0.0 0.0" rpy="0.0 0.0 0.0"/>
        <parent link="assist_link1"/>
        <child link="temp2"/>
    </joint>

    <link name="right_UpLeg">
        <inertial>
            <origin xyz="-0.02252603 -0.15352734 -0.00307775" rpy="0.0 0.0 0.0"/>
            <mass value="0.0"/>
            <inertia ixx="0.0" ixy="0.0" ixz="0.0" iyy="0.0" iyz="0.0" izz="0.0"/>
        </inertial>
        <visual>
            <origin xyz="-0.02252603 -0.15352734 -0.00307775" rpy="0.0 0.0 0.0"/>
            <geometry>
                <mesh filename="package://Humanoid/meshes/body_parts_rightUpLeg.obj" />
            </geometry>
        </visual>
        <collision>
            <origin xyz="-0.02252603 -0.15352734 -0.00307775" rpy="0.0 0.0 0.0"/>
            <geometry>
                <mesh filename="package://Humanoid/meshes/body_parts_rightUpLeg.obj" />
            </geometry>
        </collision>
    </link>

    <joint name="1" type="revolute">
        <origin xyz="-0.06767048 -0.09052169 -0.00431982" rpy="0.0 0.0 0.0"/>
        <parent link="temp1"/>
        <child link="right_UpLeg"/>
        <axis xyz="1.0 0.0 0.0"/>
        <limit lower="-2.5" upper="1.4" effort="1000.0" velocity="0.5"/>
    </joint>

    <link name="left_leg">
        <inertial>
            <origin xyz="-0.00726278 -0.16462932 -0.0345356" rpy="0.0 0.0 0.0"/>
            <mass value="0.0"/>
            <inertia ixx="0.0" ixy="0.0" ixz="0.0" iyy="0.0" iyz="0.0" izz="0.0"/>
        </inertial>
        <visual>
            <origin xyz="-0.00726278 -0.16462932 -0.0345356" rpy="0.0 0.0 0.0"/>
            <geometry>
                <mesh filename="package://Humanoid/meshes/body_parts_leftLeg.obj" />
            </geometry>
        </visual>
        <collision>
            <origin xyz="-0.00726278 -0.16462932 -0.0345356" rpy="0.0 0.0 0.0"/>
            <geometry>
                <mesh filename="package://Humanoid/meshes/body_parts_leftLeg.obj" />
            </geometry>
        </collision>
    </link>

    <joint name="5" type="revolute">
        <origin xyz="0.03427655 -0.37519857 -0.00449581" rpy="0.0 0.0 0.0"/>
        <parent link="left_UpLeg"/>
        <child link="left_leg"/>
        <axis xyz="1.0 0.0 0.0"/>
        <limit lower="-0.1" upper="2.5" effort="1000.0" velocity="0.5"/>
    </joint>

    <link name="right_leg">
        <inertial>
            <origin xyz="0.01018021 -0.15886355 -0.03476419" rpy="0.0 0.0 0.0"/>
            <mass value="0.0"/>
            <inertia ixx="0.0" ixy="0.0" ixz="0.0" iyy="0.0" iyz="0.0" izz="0.0"/>
        </inertial>
        <visual>
            <origin xyz="0.01018021 -0.15886355 -0.03476419" rpy="0.0 0.0 0.0"/>
            <geometry>
                <mesh filename="package://Humanoid/meshes/body_parts_rightLeg.obj" />
            </geometry>
        </visual>
        <collision>
            <origin xyz="0.01018021 -0.15886355 -0.03476419" rpy="0.0 0.0 0.0"/>
            <geometry>
                <mesh filename="package://Humanoid/meshes/body_parts_rightLeg.obj" />
            </geometry>
        </collision>
    </link>

    <joint name="4" type="revolute">
        <origin xyz="-0.03829005 -0.382569 -0.00885003" rpy="0.0 0.0 0.0"/>
        <parent link="right_UpLeg"/>
        <child link="right_leg"/>
        <axis xyz="1.0 0.0 0.0"/>
        <limit lower="-0.1" upper="2.5" effort="1000.0" velocity="0.5"/>
    </joint>

    <link name="left_foot">
        <inertial>
            <origin xyz="0.01451171 -0.03682505 0.03742239" rpy="0.0 0.0 0.0"/>
            <mass value="0.0"/>
            <inertia ixx="0.0" ixy="0.0" ixz="0.0" iyy="0.0" iyz="0.0" izz="0.0"/>
        </inertial>
        <visual>
            <origin xyz="0.01451171 -0.03682505 0.03742239" rpy="0.0 0.0 0.0"/>
            <geometry>
                <mesh filename="package://Humanoid/meshes/body_parts_leftFoot.obj" />
            </geometry>
        </visual>
        <collision>
            <origin xyz="0.01451171 -0.03682505 0.03742239" rpy="0.0 0.0 0.0"/>
            <geometry>
                <mesh filename="package://Humanoid/meshes/body_parts_leftFoot.obj" />
            </geometry>
        </collision>
    </link>

    <joint name="8" type="revolute">
        <origin xyz="-0.0135957 -0.39796048 -0.04369333" rpy="0.0 0.0 0.0"/>
        <parent link="left_leg"/>
        <child link="left_foot"/>
        <axis xyz="1.0 0.0 0.0"/>
        <limit lower="-0.4" upper="0.7" effort="1000.0" velocity="0.5"/>
    </joint>

    <link name="right_foot">
        <inertial>
            <origin xyz="-0.01278681 -0.02989952 0.0397387" rpy="0.0 0.0 0.0"/>
            <mass value="0.0"/>
            <inertia ixx="0.0" ixy="0.0" ixz="0.0" iyy="0.0" iyz="0.0" izz="0.0"/>
        </inertial>
        <visual>
            <origin xyz="-0.01278681 -0.02989952 0.0397387" rpy="0.0 0.0 0.0"/>
            <geometry>
                <mesh filename="package://Humanoid/meshes/body_parts_rightFoot.obj" />
            </geometry>
        </visual>
        <collision>
            <origin xyz="-0.01278681 -0.02989952 0.0397387" rpy="0.0 0.0 0.0"/>
            <geometry>
                <mesh filename="package://Humanoid/meshes/body_parts_rightFoot.obj" />
            </geometry>
        </collision>
    </link>

    <joint name="7" type="revolute">
        <origin xyz="0.01577377 -0.3984146 -0.0423118" rpy="0.0 0.0 0.0"/>
        <parent link="right_leg"/>
        <child link="right_foot"/>
        <axis xyz="1.0 0.0 0.0"/>
        <limit lower="-0.4" upper="0.7" effort="1000.0" velocity="0.5"/>
    </joint>

    <link name="left_toe">
        <inertial>
            <origin xyz="-0.0072139 -0.00405795 0.02618084" rpy="0.0 0.0 0.0"/>
            <mass value="0.0"/>
            <inertia ixx="0.0" ixy="0.0" ixz="0.0" iyy="0.0" iyz="0.0" izz="0.0"/>
        </inertial>
        <visual>
            <origin xyz="-0.0072139 -0.00405795 0.02618084" rpy="0.0 0.0 0.0"/>
            <geometry>
                <mesh filename="package://Humanoid/meshes/body_parts_leftToeBase.obj" />
            </geometry>
        </visual>
        <collision>
            <origin xyz="-0.0072139 -0.00405795 0.02618084" rpy="0.0 0.0 0.0"/>
            <geometry>
                <mesh filename="package://Humanoid/meshes/body_parts_leftToeBase.obj" />
            </geometry>
        </collision>
    </link>

    <joint name="11" type="fixed">
        <origin xyz="0.02635814 -0.05579078 0.1192884" rpy="0.0 0.0 0.0"/>
        <parent link="left_foot"/>
        <child link="left_toe"/>
        <axis xyz="0.0 0.0 0.0"/>
        <limit lower="0.0" upper="0.0" effort="0.0" velocity="0.0"/>
    </joint>

    <link name="right_toe">
        <inertial>
            <origin xyz="0.00808544 -0.00602809 0.02469485" rpy="0.0 0.0 0.0"/>
            <mass value="0.0"/>
            <inertia ixx="0.0" ixy="0.0" ixz="0.0" iyy="0.0" iyz="0.0" izz="0.0"/>
        </inertial>
        <visual>
            <origin xyz="0.00808544 -0.00602809 0.02469485" rpy="0.0 0.0 0.0"/>
            <geometry>
                <mesh filename="package://Humanoid/meshes/body_parts_rightToeBase.obj" />
            </geometry>
        </visual>
        <collision>
            <origin xyz="0.00808544 -0.00602809 0.02469485" rpy="0.0 0.0 0.0"/>
            <geometry>
                <mesh filename="package://Humanoid/meshes/body_parts_rightToeBase.obj" />
            </geometry>
        </collision>
    </link>

    <joint name="10" type="fixed">
        <origin xyz="-0.02537176 -0.04814398 0.12334795" rpy="0.0 0.0 0.0"/>
        <parent link="right_foot"/>
        <child link="right_toe"/>
        <axis xyz="0.0 0.0 0.0"/>
        <limit lower="0.0" upper="0.0" effort="0.0" velocity="0.0"/>
    </joint>

    <link name="spine">
        <inertial>
            <origin xyz="0.0029969 0.06265952 0.02763221" rpy="0.0 0.0 0.0"/>
            <mass value="0.0"/>
            <inertia ixx="0.0" ixy="0.0" ixz="0.0" iyy="0.0" iyz="0.0" izz="0.0"/>
        </inertial>
        <visual>
            <origin xyz="0.0029969 0.06265952 0.02763221" rpy="0.0 0.0 0.0"/>
            <geometry>
                <mesh filename="package://Humanoid/meshes/body_parts_spine.obj" />
            </geometry>
        </visual>
        <collision>
            <origin xyz="0.0029969 0.06265952 0.02763221" rpy="0.0 0.0 0.0"/>
            <geometry>
                <mesh filename="package://Humanoid/meshes/body_parts_spine.obj" />
            </geometry>
        </collision>
    </link>
    
    <joint name="3" type="fixed">
        <origin xyz="-0.00253287 0.10896324 -0.02669631" rpy="0.0 0.0 0.0"/>
        <parent link="hip"/>
        <child link="spine"/>
        <axis xyz="0.0 0.0 0.0"/>
        <limit lower="0.0" upper="0.0" effort="0.0" velocity="0.0"/>
    </joint>

    <link name="spine1">
        <inertial>
            <origin xyz="-0.00052418 0.02933144 0.02045965" rpy="0.0 0.0 0.0"/>
            <mass value="0.0"/>
            <inertia ixx="0.0" ixy="0.0" ixz="0.0" iyy="0.0" iyz="0.0" izz="0.0"/>
        </inertial>
        <visual>
            <origin xyz="-0.00052418 0.02933144 0.02045965" rpy="0.0 0.0 0.0"/>
            <geometry>
                <mesh filename="package://Humanoid/meshes/body_parts_spine1.obj" />
            </geometry>
        </visual>
        <collision>
            <origin xyz="-0.00052418 0.02933144 0.02045965" rpy="0.0 0.0 0.0"/>
            <geometry>
                <mesh filename="package://Humanoid/meshes/body_parts_spine1.obj" />
            </geometry>
        </collision>
    </link>

    <joint name="6" type="fixed">
        <origin xyz="0.00548704 0.13518043 0.00109247" rpy="0.0 0.0 0.0"/>
        <parent link="spine"/>
        <child link="spine1"/>
        <axis xyz="0.0 0.0 0.0"/>
        <limit lower="0.0" upper="0.0" effort="0.0" velocity="0.0"/>
    </joint>

    <link name="spine2">
        <inertial>
            <origin xyz="-0.0022121 0.09440039 -0.03596294" rpy="0.0 0.0 0.0"/>
            <mass value="0.0"/>
            <inertia ixx="0.0" ixy="0.0" ixz="0.0" iyy="0.0" iyz="0.0" izz="0.0"/>
        </inertial>
        <visual>
            <origin xyz="-0.0022121 0.09440039 -0.03596294" rpy="0.0 0.0 0.0"/>
            <geometry>
                <mesh filename="package://Humanoid/meshes/body_parts_spine2.obj" />
            </geometry>
        </visual>
        <collision>
            <origin xyz="-0.0022121 0.09440039 -0.03596294" rpy="0.0 0.0 0.0"/>
            <geometry>
                <mesh filename="package://Humanoid/meshes/body_parts_spine2.obj" />
            </geometry>
        </collision>
    </link>

    <link name="assist_link2">
        
    </link>

    <joint name="9" type="revolute">
        <origin xyz="0.001457 0.05292223 0.02542457" rpy="0.0 0.0 0.0"/>
        <parent link="spine1"/>
        <child link="assist_link2"/>
        <axis xyz="0.0 1.0 0.0"/>
        <limit lower="-1.4" upper="1.4" effort="1000.0" velocity="0.5"/>
    </joint>

    <joint name="assist_B1" type="fixed">
        <origin xyz="0.0 0.0 0.0" rpy="0.0 0.0 0.0"/>
        <parent link="assist_link2"/>
        <child link="temp14"/>
        <axis xyz="0.0 0.0 0.0"/>
        <limit lower="0.0" upper="0.0" effort="0.0" velocity="0.0"/>
    </joint>

     <joint name="assist_B2" type="fixed">
        <origin xyz="0.0 0.0 0.0" rpy="0.0 0.0 0.0"/>
        <parent link="assist_link2"/>
        <child link="spine2"/>
        <axis xyz="0.0 0.0 0.0"/>
        <limit lower="0.0" upper="0.0" effort="0.0" velocity="0.0"/>
    </joint>

     <joint name="assist_B3" type="fixed">
        <origin xyz="0.0 0.0 0.0" rpy="0.0 0.0 0.0"/>
        <parent link="assist_link2"/>
        <child link="temp13"/>
        <axis xyz="0.0 0.0 0.0"/>
        <limit lower="0.0" upper="0.0" effort="0.0" velocity="0.0"/>
    </joint>
    

    <link name="neck">
        <inertial>
            <origin xyz="0.00058504 0.03762274 0.01938053" rpy="0.0 0.0 0.0"/>
            <mass value="0.0"/>
            <inertia ixx="0.0" ixy="0.0" ixz="0.0" iyy="0.0" iyz="0.0" izz="0.0"/>
        </inertial>
        <visual>
            <origin xyz="0.00058504 0.03762274 0.01938053" rpy="0.0 0.0 0.0"/>
            <geometry>
                <mesh filename="package://Humanoid/meshes/body_parts_neck.obj" />
            </geometry>
        </visual>
        <collision>
            <origin xyz="0.00058504 0.03762274 0.01938053" rpy="0.0 0.0 0.0"/>
            <geometry>
                <mesh filename="package://Humanoid/meshes/body_parts_neck.obj" />
            </geometry>
        </collision>
    </link>

    <joint name="12" type="revolute">
        <origin xyz="-0.00277839 0.21387038 -0.04285703" rpy="0.0 0.0 0.0"/>
        <parent link="spine2"/>
        <child link="neck"/>
        <axis xyz="0.0 1.0 0.0"/>
        <limit lower="-0.6" upper="0.6" effort="1000.0" velocity="0.5"/>
    </joint>

    <link name="head">
        <inertial>
            <origin xyz="-0.00434165 0.0912436 -0.0164248" rpy="0.0 0.0 0.0"/>
            <mass value="0.0"/>
            <inertia ixx="0.0" ixy="0.0" ixz="0.0" iyy="0.0" iyz="0.0" izz="0.0"/>
        </inertial>
        <visual>
            <origin xyz="-0.00434165 0.0912436 -0.0164248" rpy="0.0 0.0 0.0"/>
            <geometry>
                <mesh filename="package://Humanoid/meshes/body_parts_head.obj" />
            </geometry>
        </visual>
        <collision>
            <origin xyz="-0.00434165 0.0912436 -0.0164248" rpy="0.0 0.0 0.0"/>
            <geometry>
                <mesh filename="package://Humanoid/meshes/body_parts_head.obj" />
            </geometry>
        </collision>
    </link>

    <joint name="15" type="fixed">
        <origin xyz="0.00515184 0.06496963 0.05134897" rpy="0.0 0.0 0.0"/>
        <parent link="neck"/>
        <child link="head"/>
        <axis xyz="0.0 0.0 0.0"/>
        <limit lower="0.0" upper="0.0" effort="0.0" velocity="0.0"/>
    </joint>

    <link name="temp14">
        <inertial>
            <origin xyz="0.0 0.0 0.0" rpy="0.0 0.0 0.0"/>
            <mass value="0.0"/>
            <inertia ixx="0.0" ixy="0.0" ixz="0.0" iyy="0.0" iyz="0.0" izz="0.0"/>
        </inertial>
        <visual name="">
            <origin xyz="0.0 0.0 0.0" rpy="0.0 0.0 0.0"/>
            <geometry>
                <box size="0.0 0.0 0.0"/>
            </geometry>
            <material name="">
                <color rgba="1.0 0.0 0.0 1.0"/>
                <texture filename=""/>
            </material>
        </visual>
        <collision>
            <origin xyz="0.0 0.0 0.0" rpy="0.0 0.0 0.0"/>
            <geometry>
                <box size="0.0 0.0 0.0"/>
            </geometry>
        </collision>
    </link>

    <joint name="14" type="fixed">
        <origin xyz="0.07884474 0.12174932 -0.03408961" rpy="0.0 0.0 0.0"/>
        <parent link="temp14"/>
        <child link="leftShoulder"/>
        <axis xyz="1.0 0.0 1.0"/>
        <limit lower="-1.0" upper="1.0" effort="1000.0" velocity="0.5"/>
    </joint>

    <link name="temp13">
        <inertial>
            <origin xyz="0.0 0.0 0.0" rpy="0.0 0.0 0.0"/>
            <mass value="0.0"/>
            <inertia ixx="0.0" ixy="0.0" ixz="0.0" iyy="0.0" iyz="0.0" izz="0.0"/>
        </inertial>
        <visual name="">
            <origin xyz="0.0 0.0 0.0" rpy="0.0 0.0 0.0"/>
            <geometry>
                <box size="0.0 0.0 0.0"/>
            </geometry>
            <material name="">
                <color rgba="1.0 0.0 0.0 1.0"/>
                <texture filename=""/>
            </material>
        </visual>
        <collision>
            <origin xyz="0.0 0.0 0.0" rpy="0.0 0.0 0.0"/>
            <geometry>
                <box size="0.0 0.0 0.0"/>
            </geometry>
        </collision>
    </link>

    <joint name="13" type="fixed">
        <origin xyz="-0.08175919 0.11883285 -0.03861528" rpy="0.0 0.0 0.0"/>
        <parent link="temp13"/>
        <child link="rightShoulder"/>
        <axis xyz="1.0 0.0 1.0"/>
        <limit lower="-1.0" upper="1.0" effort="1000.0" velocity="0.5"/>
    </joint>

    <link name="leftShoulder">
        <inertial>
            <origin xyz="0.06559623 0.02613187 -0.02027318" rpy="0.0 0.0 0.0"/>
            <mass value="0.0"/>
            <inertia ixx="0.0" ixy="0.0" ixz="0.0" iyy="0.0" iyz="0.0" izz="0.0"/>
        </inertial>
        <visual>
            <origin xyz="0.06559623 0.02613187 -0.02027318" rpy="0.0 0.0 0.0"/>
            <geometry>
                <mesh filename="package://Humanoid/meshes/body_parts_leftShoulder.obj" />
            </geometry>
        </visual>
        <collision>
            <origin xyz="0.06559623 0.02613187 -0.02027318" rpy="0.0 0.0 0.0"/>
            <geometry>
                <mesh filename="package://Humanoid/meshes/body_parts_leftShoulder.obj" />
            </geometry>
        </collision>
    </link>

    <link name="rightShoulder">
        <inertial>
            <origin xyz="-0.0667859 0.02682777 -0.01567558" rpy="0.0 0.0 0.0"/>
            <mass value="0.0"/>
            <inertia ixx="0.0" ixy="0.0" ixz="0.0" iyy="0.0" iyz="0.0" izz="0.0"/>
        </inertial>
        <visual>
            <origin xyz="-0.0667859 0.02682777 -0.01567558" rpy="0.0 0.0 0.0"/>
            <geometry>
                <mesh filename="package://Humanoid/meshes/body_parts_rightShoulder.obj" />
            </geometry>
        </visual>
        <collision>
            <origin xyz="-0.0667859 0.02682777 -0.01567558" rpy="0.0 0.0 0.0"/>
            <geometry>
                <mesh filename="package://Humanoid/meshes/body_parts_rightShoulder.obj" />
            </geometry>
        </collision>
    </link>

    <joint name="17" type="revolute">
        <origin xyz="0.09097692 0.03046888 -0.00886815" rpy="0.0 0.0 0.0"/>
        <parent link="leftShoulder"/>
        <child link="leftArm"/>
        <axis xyz="0.0 0.0 1.0"/>
        <limit lower="-1.4" upper="0.9" effort="1000.0" velocity="0.5"/>
    </joint>

    <link name="leftArm">
        <inertial>
            <origin xyz="0.12948829 -0.01228957 -0.0090026" rpy="0.0 0.0 0.0"/>
            <mass value="0.0"/>
            <inertia ixx="0.0" ixy="0.0" ixz="0.0" iyy="0.0" iyz="0.0" izz="0.0"/>
        </inertial>
        <visual>
            <origin xyz="0.12948829 -0.01228957 -0.0090026" rpy="0.0 0.0 0.0"/>
            <geometry>
                <mesh filename="package://Humanoid/meshes/body_parts_leftArm.obj" />
            </geometry>
        </visual>
        <collision>
            <origin xyz="0.12948829 -0.01228957 -0.0090026" rpy="0.0 0.0 0.0"/>
            <geometry>
                <mesh filename="package://Humanoid/meshes/body_parts_leftArm.obj" />
            </geometry>
        </collision>
    </link>

    <joint name="19" type="fixed">
        <origin xyz="0.2596122 -0.01277207 -0.02745643" rpy="0.0 0.0 0.0"/>
        <parent link="leftArm"/>
        <child link="leftForeArm"/>
    </joint>

    <link name="leftForeArm">
        <inertial>
            <origin xyz="0.10665728 0.00690599 0.00605961" rpy="0.0 0.0 0.0"/>
            <mass value="0.0"/>
            <inertia ixx="0.0" ixy="0.0" ixz="0.0" iyy="0.0" iyz="0.0" izz="0.0"/>
        </inertial>
        <visual>
            <origin xyz="0.10665728 0.00690599 0.00605961" rpy="0.0 0.0 0.0"/>
            <geometry>
                <mesh filename="package://Humanoid/meshes/body_parts_leftForeArm.obj" />
            </geometry>
        </visual>
        <collision>
            <origin xyz="0.10665728 0.00690599 0.00605961" rpy="0.0 0.0 0.0"/>
            <geometry>
                <mesh filename="package://Humanoid/meshes/body_parts_leftForeArm.obj" />
            </geometry>
        </collision>
    </link>

    <joint name="21" type="revolute">
        <origin xyz="0.2492336 0.00898604 -0.00117092" rpy="0.0 0.0 0.0"/>
        <parent link="leftForeArm"/>
        <child link="lefthand"/>
        <axis xyz="0.0 0.0 1.0"/>
        <limit lower="-1.4" upper="0.6" effort="1000.0" velocity="0.5"/>
    </joint>

    <link name="lefthand">
        <inertial>
            <origin xyz="0.08488861 -0.00938576 0.00616219" rpy="0.0 0.0 0.0"/>
            <mass value="0.0"/>
            <inertia ixx="0.0" ixy="0.0" ixz="0.0" iyy="0.0" iyz="0.0" izz="0.0"/>
        </inertial>
        <visual>
            <origin xyz="0.08488861 -0.00938576 0.00616219" rpy="0.0 0.0 0.0"/>
            <geometry>
                <mesh filename="package://Humanoid/meshes/body_parts_leftHand.obj" />
            </geometry>
        </visual>
        <collision>
            <origin xyz="0.08488861 -0.00938576 0.00616219" rpy="0.0 0.0 0.0"/>
            <geometry>
                <mesh filename="package://Humanoid/meshes/body_parts_leftHand.obj" />
            </geometry>
        </collision>
    </link>

    <joint name="16" type="revolute">
        <origin xyz="-0.09601238 0.03255117 -0.00914307" rpy="0.0 0.0 0.0"/>
        <parent link="rightShoulder"/>
        <child link="rightArm"/>
        <axis xyz="0.0 0.0 1.0"/>
        <limit lower="-1.4" upper="0.9" effort="1000.0" velocity="0.5"/>
    </joint>

    <link name="rightArm">
        <inertial>
            <origin xyz="-0.12550239 -0.01296561 -0.00590812" rpy="0.0 0.0 0.0"/>
            <mass value="0.0"/>
            <inertia ixx="0.0" ixy="0.0" ixz="0.0" iyy="0.0" iyz="0.0" izz="0.0"/>
        </inertial>
        <visual>
            <origin xyz="-0.12550239 -0.01296561 -0.00590812" rpy="0.0 0.0 0.0"/>
            <geometry>
                <mesh filename="package://Humanoid/meshes/body_parts_rightArm.obj" />
            </geometry>
        </visual>
        <collision>
            <origin xyz="-0.12550239 -0.01296561 -0.00590812" rpy="0.0 0.0 0.0"/>
            <geometry>
                <mesh filename="package://Humanoid/meshes/body_parts_rightArm.obj" />
            </geometry>
        </collision>
    </link>

    <joint name="18" type="fixed">
        <origin xyz="-0.25374195 -0.01332924 -0.02140098" rpy="0.0 0.0 0.0"/>
        <parent link="rightArm"/>
        <child link="rightForeArm"/>
    </joint>

    <link name="rightForeArm">
        <inertial>
            <origin xyz="-0.10992141 0.00679169 0.00313351" rpy="0.0 0.0 0.0"/>
            <mass value="0.0"/>
            <inertia ixx="0.0" ixy="0.0" ixz="0.0" iyy="0.0" iyz="0.0" izz="0.0"/>
        </inertial>
        <visual>
            <origin xyz="-0.10992141 0.00679169 0.00313351" rpy="0.0 0.0 0.0"/>
            <geometry>
                <mesh filename="package://Humanoid/meshes/body_parts_rightForeArm.obj" />
            </geometry>
        </visual>
        <collision>
            <origin xyz="-0.10992141 0.00679169 0.00313351" rpy="0.0 0.0 0.0"/>
            <geometry>
                <mesh filename="package://Humanoid/meshes/body_parts_rightForeArm.obj" />
            </geometry>
        </collision>
    </link>

    <joint name="20" type="revolute">
        <origin xyz="-0.2552981 0.0077723 -0.0055592" rpy="0.0 0.0 0.0"/>
        <parent link="rightForeArm"/>
        <child link="rightHand"/>
        <axis xyz="0.0 0.0 1.0"/>
        <limit lower="-1.4" upper="0.6" effort="1000.0" velocity="0.5"/>
    </joint>

    <link name="rightHand">
        <inertial>
            <origin xyz="-0.08138476 -0.00979895 0.0080402" rpy="0.0 0.0 0.0"/>
            <mass value="0.0"/>
            <inertia ixx="0.0" ixy="0.0" ixz="0.0" iyy="0.0" iyz="0.0" izz="0.0"/>
        </inertial>
        <visual>
            <origin xyz="-0.08138476 -0.00979895 0.0080402" rpy="0.0 0.0 0.0"/>
            <geometry>
                <mesh filename="package://Humanoid/meshes/body_parts_rightHand.obj" />
            </geometry>
        </visual>
        <collision>
            <origin xyz="-0.08138476 -0.00979895 0.0080402" rpy="0.0 0.0 0.0"/>
            <geometry>
                <mesh filename="package://Humanoid/meshes/body_parts_rightHand.obj" />
            </geometry>
        </collision>
    </link>

</robot>
