<?xml version="1.0" ?>
<robot name="Humanoid">

	<link name="root">
		<inertial>
			<origin xyz="0.0 0.0 0.0" rpy="0.0 0.0 0.0"/>
			<mass value="0.00001"/>
			<inertia ixx="0.1" ixy="0.0" ixz="0.0" iyy="0.1" iyz="0.0" izz="0.1"/>
		</inertial>
		<visual>
			<origin xyz="0.0 0.0 0.0" rpy="0.0 0.0 0.0"/>
			<geometry>
				<sphere radius="0.000001" />
			</geometry>
		</visual>
		<collision>
			<origin xyz="0.0 0.0 0.0" rpy="0.0 0.0 0.0"/>
			<geometry>
				<sphere radius="0.00000004" />
			</geometry>
		</collision>
	</link>

	<link name="root_ori">
		<inertial>
			<origin xyz="-0.00179506 -0.22333345 0.02821913" rpy="0.0 0.0 0.0"/>
			<mass value="0.0"/>
			<inertia ixx="0.0" ixy="0.0" ixz="0.0" iyy="0.0" iyz="0.0" izz="0.0"/>
		</inertial>
		<visual>
			<origin xyz="-0.00179506 -0.22333345 0.02821913" rpy="0.0 0.0 0.0"/>
			<geometry>
				<sphere radius="0.07"/>
			</geometry>
		</visual>
		<collision>
			<origin xyz="-0.00179506 -0.22333345 0.02821913" rpy="0.0 0.0 0.0"/>
			<geometry>
				<sphere radius="0.07"/>
			</geometry>
		</collision>
	</link>

	<joint name="root_joint" type="fixed">
		<origin xyz="-0.00179506 -0.22333345 0.02821913" rpy="0.0 0.0 0.0"/>
		<parent link="root"/>
		<child link="root_ori"/>
	</joint>
	
	<link name="left_hip">
		<inertial>
			<origin xyz="0.00057561 -0.00681268 -0.01696218" rpy="0.0 0.0 0.0"/>
			<mass value="0.00004"/>
			<inertia ixx="0.1" ixy="0.0" ixz="0.0" iyy="0.1" iyz="0.0" izz="0.1"/>
		</inertial>
		<visual>
			<origin xyz="0.00057561 -0.00681268 -0.01696218" rpy="0.0 0.0 0.0"/>
			<geometry>
				<mesh filename="package://Humanoid/meshes/body_parts_hips.obj" />
			</geometry>
		</visual>
		<collision>
			<origin xyz="0.00057561 -0.00681268 -0.01696218" rpy="0.0 0.0 0.0"/>
			<geometry>
				<mesh filename="package://Humanoid/meshes/body_parts_hips.obj" />
			</geometry>
		</collision>
	</link>

	<joint name="left_hip_joint" type="revolute">
		<origin xyz="0.06951974 -0.09140623 -0.00681533" rpy="0.0 0.0 0.0"/>
		<parent link="root_ori"/>
		<child link="left_hip"/>
		<axis xyz="0.0 1.0 0.0"/>
		<limit lower="-2.5" upper="1.4" effort="1000.0" velocity="0.5"/>
	</joint>

	<link name="right_hip">
		<inertial>
			<origin xyz="0.00057561 -0.00681268 -0.01696218" rpy="0.0 0.0 0.0"/>
			<mass value="0.00004"/>
			<inertia ixx="0.1" ixy="0.0" ixz="0.0" iyy="0.1" iyz="0.0" izz="0.1"/>
		</inertial>
		<visual>
			<origin xyz="0.00057561 -0.00681268 -0.01696218" rpy="0.0 0.0 0.0"/>
			<geometry>
				<mesh filename="package://Humanoid/meshes/body_parts_hips.obj" />
			</geometry>
		</visual>
		<collision>
			<origin xyz="0.00057561 -0.00681268 -0.01696218" rpy="0.0 0.0 0.0"/>
			<geometry>
				<mesh filename="package://Humanoid/meshes/body_parts_hips.obj" />
			</geometry>
		</collision>
	</link>

	<joint name="right_hip_joint" type="revolute">
		<origin xyz="0.06951974 -0.09140623 -0.00681533" rpy="0.0 0.0 0.0"/>
		<parent link="root_ori"/>
		<child link="right_hip"/>
		<axis xyz="0.0 1.0 0.0"/>
		<limit lower="-2.5" upper="1.4" effort="1000.0" velocity="0.5"/>
	</joint>

	<link name="spine1">
		<inertial>
			<origin xyz="0.0029969 0.06265952 0.02763221" rpy="0.0 0.0 0.0"/>
			<mass value="0.000001"/>
			<inertia ixx="0.1" ixy="0.0" ixz="0.0" iyy="0.1" iyz="0.0" izz="0.1"/>
		</inertial>
		<visual>
			<origin xyz="0.0029969 0.06265952 0.02763221" rpy="0.0 0.0 0.0"/>
			<geometry>
				<mesh filename="package://Humanoid/meshes/body_parts_spine.obj" />
			</geometry>
		</visual>
		<collision>
			<origin xyz="0.0029969 0.06265952 0.02763221" rpy="0.0 0.0 0.0"/>
			<geometry>
				<mesh filename="package://Humanoid/meshes/body_parts_spine.obj" />
			</geometry>
		</collision>
	</link>

	<joint name="spine1_joint" type="fixed">
		<origin xyz="-0.00253287 0.10896324 -0.02669631" rpy="0.0 0.0 0.0"/>
		<parent link="root_ori"/>
		<child link="spine1"/>
	</joint>

	<link name="left_knee">
		<inertial>
			<origin xyz="0.02136212 -0.15149257 0.00267958" rpy="0.0 0.0 0.0"/>
			<mass value="0.000001"/>
			<inertia ixx="0.1" ixy="0.0" ixz="0.0" iyy="0.1" iyz="0.0" izz="0.1"/>
		</inertial>
		<visual>
			<origin xyz="0.02136212 -0.15149257 0.00267958" rpy="0.0 0.0 0.0"/>
			<geometry>
				<mesh filename="package://Humanoid/meshes/body_parts_leftUpLeg.obj" />
			</geometry>
		</visual>
		<collision>
			<origin xyz="0.02136212 -0.15149257 0.00267958" rpy="0.0 0.0 0.0"/>
			<geometry>
				<mesh filename="package://Humanoid/meshes/body_parts_leftUpLeg.obj" />
			</geometry>
		</collision>
	</link>

	<joint name="left_knee_joint" type="revolute">
		<origin xyz="0.03427655 -0.37519857 -0.00449581" rpy="0.0 0.0 0.0"/>
		<parent link="left_hip"/>
		<child link="left_knee"/>
		<axis xyz="0.0 1.0 0.0"/>
		<limit lower="-0.1" upper="2.5" effort="1000.0" velocity="0.5"/>
	</joint>

	<link name="right_knee">
		<inertial>
			<origin xyz="-0.02252603 -0.15352734 -0.00307775" rpy="0.0 0.0 0.0"/>
			<mass value="0.00001"/>
			<inertia ixx="0.1" ixy="0.0" ixz="0.0" iyy="0.1" iyz="0.0" izz="0.1"/>
		</inertial>
		<visual>
			<origin xyz="-0.02252603 -0.15352734 -0.00307775" rpy="0.0 0.0 0.0"/>
			<geometry>
				<mesh filename="package://Humanoid/meshes/body_parts_rightUpLeg.obj" />
			</geometry>
		</visual>
		<collision>
			<origin xyz="-0.02252603 -0.15352734 -0.00307775" rpy="0.0 0.0 0.0"/>
			<geometry>
				<mesh filename="package://Humanoid/meshes/body_parts_rightUpLeg.obj" />
			</geometry>
		</collision>
	</link>

	<joint name="right_knee_joint" type="revolute">
		<origin xyz="-0.03829005 -0.382569 -0.00885003" rpy="0.0 0.0 0.0"/>
		<parent link="right_hip"/>
		<child link="right_knee"/>
		<axis xyz="0.0 1.0 0.0"/>
		<limit lower="-0.1" upper="2.5" effort="1000.0" velocity="0.5"/>
	</joint>

	<link name="spine2">
		<inertial>
			<origin xyz="-0.00052418 0.02933144 0.02045965" rpy="0.0 0.0 0.0"/>
			<mass value="0.000001"/>
			<inertia ixx="0.1" ixy="0.0" ixz="0.0" iyy="0.1" iyz="0.0" izz="0.1"/>
		</inertial>
		<visual>
			<origin xyz="-0.00052418 0.02933144 0.02045965" rpy="0.0 0.0 0.0"/>
			<geometry>
				<mesh filename="package://Humanoid/meshes/body_parts_spine1.obj" />
			</geometry>
		</visual>
		<collision>
			<origin xyz="-0.00052418 0.02933144 0.02045965" rpy="0.0 0.0 0.0"/>
			<geometry>
				<mesh filename="package://Humanoid/meshes/body_parts_spine1.obj" />
			</geometry>
		</collision>
	</link>

	<joint name="spine2_joint" type="fixed">
		<origin xyz="0.00548704 0.13518043 0.00109247" rpy="0.0 0.0 0.0"/>
		<parent link="spine1"/>
		<child link="spine2"/>
	</joint>

	<link name="left_ankle">
		<inertial>
			<origin xyz="-0.00726278 -0.16462932 -0.0345356" rpy="0.0 0.0 0.0"/>
			<mass value="0.00001"/>
			<inertia ixx="0.1" ixy="0.0" ixz="0.0" iyy="0.1" iyz="0.0" izz="0.1"/>
		</inertial>
		<visual>
			<origin xyz="-0.00726278 -0.16462932 -0.0345356" rpy="0.0 0.0 0.0"/>
			<geometry>
				<mesh filename="package://Humanoid/meshes/body_parts_leftLeg.obj" />
			</geometry>
		</visual>
		<collision>
			<origin xyz="-0.00726278 -0.16462932 -0.0345356" rpy="0.0 0.0 0.0"/>
			<geometry>
				<mesh filename="package://Humanoid/meshes/body_parts_leftLeg.obj" />
			</geometry>
		</collision>
	</link>

	<joint name="left_ankle_joint" type="revolute">
		<origin xyz="-0.0135957 -0.39796048 -0.04369333" rpy="0.0 0.0 0.0"/>
		<parent link="left_knee"/>
		<child link="left_ankle"/>
		<axis xyz="0.0 1.0 0.0"/>
		<limit lower="-0.4" upper="0.7" effort="1000.0" velocity="0.5"/>
	</joint>

	<link name="right_ankle">
		<inertial>
			<origin xyz="0.01018021 -0.15886355 -0.03476419" rpy="0.0 0.0 0.0"/>
			<mass value="0.00001"/>
			<inertia ixx="0.0" ixy="0.0" ixz="0.0" iyy="0.0" iyz="0.0" izz="0.0"/>
		</inertial>
		<visual>
			<origin xyz="0.01018021 -0.15886355 -0.03476419" rpy="0.0 0.0 0.0"/>
			<geometry>
				<mesh filename="package://Humanoid/meshes/body_parts_rightLeg.obj" />
			</geometry>
		</visual>
		<collision>
			<origin xyz="0.01018021 -0.15886355 -0.03476419" rpy="0.0 0.0 0.0"/>
			<geometry>
				<mesh filename="package://Humanoid/meshes/body_parts_rightLeg.obj" />
			</geometry>
		</collision>
	</link>

	<joint name="right_ankle_joint" type="revolute">
		<origin xyz="0.01577377 -0.3984146 -0.0423118" rpy="0.0 0.0 0.0"/>
		<parent link="right_knee"/>
		<child link="right_ankle"/>
		<axis xyz="0.0 1.0 0.0"/>
		<limit lower="-0.4" upper="0.7" effort="1000.0" velocity="0.5"/>
	</joint>

	<link name="spine3">
		<inertial>
			<origin xyz="-0.0022121 0.09440039 -0.03596294" rpy="0.0 0.0 0.0"/>
			<mass value="0.000001"/>
			<inertia ixx="0.1" ixy="0.0" ixz="0.0" iyy="0.1" iyz="0.0" izz="0.1"/>
		</inertial>
		<visual>
			<origin xyz="-0.0022121 0.09440039 -0.03596294" rpy="0.0 0.0 0.0"/>
			<geometry>
				<mesh filename="package://Humanoid/meshes/body_parts_spine2.obj" />
			</geometry>
		</visual>
		<collision>
			<origin xyz="-0.0022121 0.09440039 -0.03596294" rpy="0.0 0.0 0.0"/>
			<geometry>
				<mesh filename="package://Humanoid/meshes/body_parts_spine2.obj" />
			</geometry>
		</collision>
	</link>

	<joint name="spine3_joint" type="fixed">
		<origin xyz="0.001457 0.05292223 0.02542457" rpy="0.0 0.0 0.0"/>
		<parent link="spine2"/>
		<child link="spine3"/>
	</joint>

	<link name="left_foot">
		<inertial>
			<origin xyz="0.01451171 -0.03682505 0.03742239" rpy="0.0 0.0 0.0"/>
			<mass value="0.00001"/>
			<inertia ixx="0.1" ixy="0.0" ixz="0.0" iyy="0.1" iyz="0.0" izz="0.1"/>
		</inertial>
		<visual>
			<origin xyz="0.01451171 -0.03682505 0.03742239" rpy="0.0 0.0 0.0"/>
			<geometry>
				<mesh filename="package://Humanoid/meshes/body_parts_leftFoot.obj" />
			</geometry>
		</visual>
		<collision>
			<origin xyz="0.01451171 -0.03682505 0.03742239" rpy="0.0 0.0 0.0"/>
			<geometry>
				<mesh filename="package://Humanoid/meshes/body_parts_leftFoot.obj" />
			</geometry>
		</collision>
	</link>

	<joint name="left_foot_joint" type="fixed">
		<origin xyz="0.02635814 -0.05579078 0.1192884" rpy="0.0 0.0 0.0"/>
		<parent link="left_ankle"/>
		<child link="left_foot"/>
	</joint>

	<link name="right_foot">
		<inertial>
			<origin xyz="-0.01278681 -0.02989952 0.0397387" rpy="0.0 0.0 0.0"/>
			<mass value="0.00001"/>
			<inertia ixx="0.1" ixy="0.0" ixz="0.0" iyy="0.1" iyz="0.0" izz="0.1"/>
		</inertial>
		<visual>
			<origin xyz="-0.01278681 -0.02989952 0.0397387" rpy="0.0 0.0 0.0"/>
			<geometry>
				<mesh filename="package://Humanoid/meshes/body_parts_rightFoot.obj" />
			</geometry>
		</visual>
		<collision>
			<origin xyz="-0.01278681 -0.02989952 0.0397387" rpy="0.0 0.0 0.0"/>
			<geometry>
				<mesh filename="package://Humanoid/meshes/body_parts_rightFoot.obj" />
			</geometry>
		</collision>
	</link>

	<joint name="right_foot_joint" type="fixed">
		<origin xyz="-0.02537176 -0.04814398 0.12334795" rpy="0.0 0.0 0.0"/>
		<parent link="right_ankle"/>
		<child link="right_foot"/>
	</joint>

	<link name="neck">
		<inertial>
			<origin xyz="0.00058504 0.03762274 0.01938053" rpy="0.0 0.0 0.0"/>
			<mass value="0.00001"/>
			<inertia ixx="0.1" ixy="0.0" ixz="0.0" iyy="0.1" iyz="0.0" izz="0.1"/>
		</inertial>
		<visual>
			<origin xyz="0.00058504 0.03762274 0.01938053" rpy="0.0 0.0 0.0"/>
			<geometry>
				<mesh filename="package://Humanoid/meshes/body_parts_neck.obj" />
			</geometry>
		</visual>
		<collision>
			<origin xyz="0.00058504 0.03762274 0.01938053" rpy="0.0 0.0 0.0"/>
			<geometry>
				<mesh filename="package://Humanoid/meshes/body_parts_neck.obj" />
			</geometry>
		</collision>
	</link>

	<joint name="neck_joint" type="revolute">
		<origin xyz="-0.00277839 0.21387038 -0.04285703" rpy="0.0 0.0 0.0"/>
		<parent link="spine3"/>
		<child link="neck"/>
		<axis xyz="0.0 1.0 0.0"/>
		<limit lower="-0.6" upper="0.6" effort="1000.0" velocity="0.5"/>
	</joint>

	<link name="left_collar">
		<inertial>
			<origin xyz="0.07884474 0.12174932 -0.03408961" rpy="0.0 0.0 0.0"/>
			<mass value="0.00001"/>
			<inertia ixx="0.1" ixy="0.0" ixz="0.0" iyy="0.1" iyz="0.0" izz="0.1"/>
		</inertial>
		<visual>
			<origin xyz="0.07884474 0.12174932 -0.03408961" rpy="0.0 0.0 0.0"/>
			<geometry>
				<box size="0.1 0.1 0.1"/>
			</geometry>
		</visual>
		<collision>
			<origin xyz="0.07884474 0.12174932 -0.03408961" rpy="0.0 0.0 0.0"/>
			<geometry>
				<box size="0.1 0.1 0.1"/>
			</geometry>
		</collision>
	</link>

	<joint name="left_collar_joint" type="fixed">
		<origin xyz="0.07884474 0.12174932 -0.03408961" rpy="0.0 0.0 0.0"/>
		<parent link="neck"/>
		<child link="left_collar"/>
	</joint>

	<link name="right_collar">
		<inertial>
			<origin xyz="-0.08175919 0.11883285 -0.03861528" rpy="0.0 0.0 0.0"/>
			<mass value="0.00001"/>
			<inertia ixx="0.1" ixy="0.0" ixz="0.0" iyy="0.1" iyz="0.0" izz="0.1"/>
		</inertial>
		<visual>
			<origin xyz="-0.08175919 0.11883285 -0.03861528" rpy="0.0 0.0 0.0"/>
			<geometry>
				<box size="0.1 0.1 0.1"/>
			</geometry>
		</visual>
		<collision>
			<origin xyz="-0.08175919 0.11883285 -0.03861528" rpy="0.0 0.0 0.0"/>
			<geometry>
				<box size="0.1 0.1 0.1"/>
			</geometry>
		</collision>
	</link>

	<joint name="right_collar_joint" type="fixed">
		<origin xyz="-0.08175919 0.11883285 -0.03861528" rpy="0.0 0.0 0.0"/>
		<parent link="neck"/>
		<child link="right_collar"/>
	</joint>

	<link name="head">
		<inertial>
			<origin xyz="-0.00434165 0.0912436 -0.0164248" rpy="0.0 0.0 0.0"/>
			<mass value="0.00001"/>
			<inertia ixx="0.1" ixy="0.0" ixz="0.0" iyy="0.1" iyz="0.0" izz="0.1"/>
		</inertial>
		<visual>
			<origin xyz="-0.00434165 0.0912436 -0.0164248" rpy="0.0 0.0 0.0"/>
			<geometry>
				<mesh filename="package://Humanoid/meshes/body_parts_head.obj" />
			</geometry>
		</visual>
		<collision>
			<origin xyz="-0.00434165 0.0912436 -0.0164248" rpy="0.0 0.0 0.0"/>
			<geometry>
				<mesh filename="package://Humanoid/meshes/body_parts_head.obj" />
			</geometry>
		</collision>
	</link>

	<joint name="head_joint" type="fixed">
		<origin xyz="0.00515184 0.06496963 0.05134897" rpy="0.0 0.0 0.0"/>
		<parent link="neck"/>
		<child link="head"/>
	</joint>

	<link name="left_shoulder">
		<inertial>
			<origin xyz="0.06559623 0.02613187 -0.02027318" rpy="0.0 0.0 0.0"/>
			<mass value="0.00001"/>
			<inertia ixx="0.1" ixy="0.0" ixz="0.0" iyy="0.1" iyz="0.0" izz="0.1"/>
		</inertial>
		<visual>
			<origin xyz="0.06559623 0.02613187 -0.02027318" rpy="0.0 0.0 0.0"/>
			<geometry>
				<mesh filename="package://Humanoid/meshes/body_parts_leftShoulder.obj" />
			</geometry>
		</visual>
		<collision>
			<origin xyz="0.06559623 0.02613187 -0.02027318" rpy="0.0 0.0 0.0"/>
			<geometry>
				<mesh filename="package://Humanoid/meshes/body_parts_leftShoulder.obj" />
			</geometry>
		</collision>
	</link>

	<joint name="left_shoulder_joint" type="revolute">
		<origin xyz="0.09097692 0.03046888 -0.00886815" rpy="0.0 0.0 0.0"/>
		<parent link="left_collar"/>
		<child link="left_shoulder"/>
		<axis xyz="1.0 1.0 0.0"/>
		<limit lower="-1.0" upper="1.0" effort="1000.0" velocity="0.5"/>
	</joint>

	<link name="right_shoulder">
		<inertial>
			<origin xyz="-0.0667859 0.02682777 -0.01567558" rpy="0.0 0.0 0.0"/>
			<mass value="0.00001"/>
			<inertia ixx="0.1" ixy="0.0" ixz="0.0" iyy="0.1" iyz="0.0" izz="0.1"/>
		</inertial>
		<visual>
			<origin xyz="-0.0667859 0.02682777 -0.01567558" rpy="0.0 0.0 0.0"/>
			<geometry>
				<mesh filename="package://Humanoid/meshes/body_parts_rightShoulder.obj" />
			</geometry>
		</visual>
		<collision>
			<origin xyz="-0.0667859 0.02682777 -0.01567558" rpy="0.0 0.0 0.0"/>
			<geometry>
				<mesh filename="package://Humanoid/meshes/body_parts_rightShoulder.obj" />
			</geometry>
		</collision>
	</link>

	<joint name="right_shoulder_joint" type="revolute">
		<origin xyz="-0.09601238 0.03255117 -0.00914307" rpy="0.0 0.0 0.0"/>
		<parent link="right_collar"/>
		<child link="right_shoulder"/>
		<axis xyz="1.0 1.0 0.0"/>
		<limit lower="-1.0" upper="1.0" effort="1000.0" velocity="0.5"/>
	</joint>

    <link name="left_elbow">
		<inertial>
			<origin xyz="0.12948829 -0.01228957 -0.0090026" rpy="0.0 0.0 0.0"/>
			<mass value="0.00001"/>
			<inertia ixx="0.1" ixy="0.0" ixz="0.0" iyy="0.1" iyz="0.0" izz="0.1"/>
		</inertial>
		<visual>
			<origin xyz="0.12948829 -0.01228957 -0.0090026" rpy="0.0 0.0 0.0"/>
			<geometry>
				<mesh filename="package://Humanoid/meshes/body_parts_leftArm.obj" />
			</geometry>
		</visual>
		<collision>
			<origin xyz="0.12948829 -0.01228957 -0.0090026" rpy="0.0 0.0 0.0"/>
			<geometry>
				<mesh filename="package://Humanoid/meshes/body_parts_leftArm.obj" />
			</geometry>
		</collision>
	</link>

	<joint name="left_elbow_joint" type="revolute">
		<origin xyz="0.2596122 -0.01277207 -0.02745643" rpy="0.0 0.0 0.0"/>
		<parent link="left_shoulder"/>
		<child link="left_elbow"/>
		<axis xyz="0.0 1.0 1.0"/>
		<limit lower="-2.7" upper="0.0" effort="1000.0" velocity="0.5"/>
	</joint>

	<link name="right_elbow">
		<inertial>
			<origin xyz="-0.12550239 -0.01296561 -0.00590812" rpy="0.0 0.0 0.0"/>
			<mass value="0.00001"/>
			<inertia ixx="0.1" ixy="0.0" ixz="0.0" iyy="0.1" iyz="0.0" izz="0.1"/>
		</inertial>
		<visual>
			<origin xyz="-0.12550239 -0.01296561 -0.00590812" rpy="0.0 0.0 0.0"/>
			<geometry>
				<mesh filename="package://Humanoid/meshes/body_parts_rightArm.obj" />
			</geometry>
		</visual>
		<collision>
			<origin xyz="-0.12550239 -0.01296561 -0.00590812" rpy="0.0 0.0 0.0"/>
			<geometry>
				<mesh filename="package://Humanoid/meshes/body_parts_rightArm.obj" />
			</geometry>
		</collision>
	</link>

	<joint name="right_elbow_joint" type="revolute">
		<origin xyz="-0.25374195 -0.01332924 -0.02140098" rpy="0.0 0.0 0.0"/>
		<parent link="right_shoulder"/>
		<child link="right_elbow"/>
		<axis xyz="0.0 1.0 1.0"/>
		<limit lower="-2.7" upper="0.0" effort="1000.0" velocity="0.5"/>
	</joint>

	<link name="left_fore_arm">
		<inertial>
			<origin xyz="0.10665728 0.00690599 0.00605961" rpy="0.0 0.0 0.0"/>
			<mass value="0.00001"/>
			<inertia ixx="0.1" ixy="0.0" ixz="0.0" iyy="0.1" iyz="0.0" izz="0.1"/>
		</inertial>
		<visual>
			<origin xyz="0.10665728 0.00690599 0.00605961" rpy="0.0 0.0 0.0"/>
			<geometry>
				<mesh filename="package://Humanoid/meshes/body_parts_leftForeArm.obj" />
			</geometry>
		</visual>
		<collision>
			<origin xyz="0.0 0.0 0.0" rpy="0.0 0.0 0.0"/>
			<geometry>
				<box size="0.0 0.0 0.0"/>
			</geometry>
		</collision>
	</link>

	<joint name="left_fore_arm_joint" type="fixed">
		<origin xyz="0.2492336 0.00898604 -0.00117092" rpy="0.0 0.0 0.0"/>
		<parent link="left_elbow"/>
		<child link="left_fore_arm"/>
		<axis xyz="0.0 0.0 0.0"/>
		<limit lower="0.0" upper="0.0" effort="0.0" velocity="0.0"/>
	</joint>

	<link name="right_fore_arm">
		<inertial>
			<origin xyz="-0.10992141 0.00679169 0.00313351" rpy="0.0 0.0 0.0"/>
			<mass value="0.00001"/>
			<inertia ixx="0.1" ixy="0.0" ixz="0.0" iyy="0.1" iyz="0.0" izz="0.1"/>
		</inertial>
		<visual>
			<origin xyz="-0.10992141 0.00679169 0.00313351" rpy="0.0 0.0 0.0"/>
			<geometry>
				<mesh filename="package://Humanoid/meshes/body_parts_rightForeArm.obj" />
			</geometry>
		</visual>
		<collision>
			<origin xyz="0.0 0.0 0.0" rpy="0.0 0.0 0.0"/>
			<geometry>
				<box size="0.0 0.0 0.0"/>
			</geometry>
		</collision>
	</link>

	<joint name="right_fore_arm_joint" type="fixed">
		<origin xyz="-0.2552981 0.0077723 -0.0055592" rpy="0.0 0.0 0.0"/>
		<parent link="right_elbow"/>
		<child link="right_fore_arm"/>
		<axis xyz="0.0 0.0 0.0"/>
		<limit lower="0.0" upper="0.0" effort="0.0" velocity="0.0"/>
	</joint>

	<link name="left_hand">
		<inertial>
			<origin xyz="0.08488861 -0.00938576 0.00616219" rpy="0.0 0.0 0.0"/>
			<mass value="0.000001"/>
			<inertia ixx="0.1" ixy="0.0" ixz="0.0" iyy="0.1" iyz="0.0" izz="0.1"/>
		</inertial>
		<visual>
			<origin xyz="0.08488861 -0.00938576 0.00616219" rpy="0.0 0.0 0.0"/>
			<geometry>
				<mesh filename="package://Humanoid/meshes/body_parts_leftHand.obj" />
			</geometry>
		</visual>
		<collision>
			<origin xyz="0.0 0.0 0.0" rpy="0.0 0.0 0.0"/>
			<geometry>
				<box size="0.0 0.0 0.0"/>
			</geometry>
		</collision>
	</link>

	<joint name="left_hand_joint" type="revolute">
		<origin xyz="0.08404213 -0.00816153 -0.01494537" rpy="0.0 0.0 0.0"/>
		<parent link="left_fore_arm"/>
		<child link="left_hand"/>
		<axis xyz="0.0 1.0 0.0"/>
		<limit lower="0.0" upper="0.0" effort="1000.0" velocity="0.5"/>
	</joint>

	<link name="right_hand">
		<inertial>
			<origin xyz="-0.08138476 -0.00979895 0.0080402" rpy="0.0 0.0 0.0"/>
			<mass value="0.000001"/>
			<inertia ixx="0.1" ixy="0.0" ixz="0.0" iyy="0.1" iyz="0.0" izz="0.1"/>
		</inertial>
		<visual>
			<origin xyz="-0.08138476 -0.00979895 0.0080402" rpy="0.0 0.0 0.0"/>
			<geometry>
				<mesh filename="package://Humanoid/meshes/body_parts_rightHand.obj" />
			</geometry>
		</visual>
		<collision>
			<origin xyz="0.0 0.0 0.0" rpy="0.0 0.0 0.0"/>
			<geometry>
				<box size="0.0 0.0 0.0"/>
			</geometry>
		</collision>
	</link>

	<joint name="right_hand_joint" type="revolute">
		<origin xyz="-0.08462191 -0.00611724 -0.01031508" rpy="0.0 0.0 0.0"/>
		<parent link="right_fore_arm"/>
		<child link="right_hand"/>
		<axis xyz="0.0 1.0 0.0"/>
		<limit lower="0.0" upper="0.0" effort="1000.0" velocity="0.5"/>
	</joint>
</robot>
