<?xml version="1.0"?>
<robot name="Humanoid">
    <link name="root">
		
	</link>

    <link name="assist_link1">
        
    </link>

    <joint name="0" type="fixed">
        <origin xyz="0 0 0" rpy="0.0 0.0 0.0"/>
        <parent link="root"/>
        <child link="assist_link1"/>
        <axis xyz="0.0 0.0 0.0"/>
        <limit lower="0.0" upper="0.0" effort="0.0" velocity="0.0"/>
    </joint>

    <joint name="assist_jointA1" type="fixed">
        <origin xyz="0.0 0.0 0.0" rpy="0.0 0.0 0.0"/>
        <parent link="assist_link1"/>
        <child link="hip_rx"/>
        <axis xyz="0.0 0.0 0.0"/>
        <limit lower="0.0" upper="0.0" effort="0.0" velocity="0.0"/>
    </joint>

    <link name="hip_rx">
        <visual>
            <origin xyz="0.00057561 -0.00681268 -0.01696218" rpy="0.0 0.0 0.0"/>
            <geometry>
                <mesh filename="package://Humanoid/meshes/body_parts_hips.obj" />
            </geometry>
        </visual>
        <collision>
            <origin xyz="0.00057561 -0.00681268 -0.01696218" rpy="0.0 0.0 0.0"/>
            <geometry>
                <mesh filename="package://Humanoid/meshes/body_parts_hips.obj" />
            </geometry>
        </collision>
    </link>

    <joint name="assist_jointA2" type="fixed">
        <origin xyz="0.0 0.0 0.0" rpy="0.0 0.0 0.0"/>
        <parent link="assist_link1"/>
        <child link="temp1_rx"/>
        <axis xyz="0.0 0.0 0.0"/>
        <limit lower="0.0" upper="0.0" effort="0.0" velocity="0.0"/>
    </joint>

    <joint name="assist_jointA3" type="fixed">
        <origin xyz="0.0 0.0 0.0" rpy="0.0 0.0 0.0"/>
        <parent link="assist_link1"/>
        <child link="temp2_rx"/>
    </joint>

    <link name="temp2_rx">
        
    </link>

    <joint name="1_rx" type="revolute">
        <origin xyz="0.06951974 -0.09140623 -0.00681533" rpy="0.0 0.0 0.0"/>
        <parent link="temp2_rx"/>
        <child link="temp2_ry"/>
        <axis xyz="1.0 0.0 0.0"/>
        <limit lower="-2.2" upper="1.1" effort="1000.0" velocity="0.5"/>
    </joint>

    <link name="temp2_ry">
        
    </link>

    <joint name="1_ry" type="revolute">
        <origin xyz="0 0 0" rpy="0.0 0.0 0.0"/>
        <parent link="temp2_ry"/>
        <child link="temp2_rz"/>
        <axis xyz="0.0 1.0 0.0"/>
        <limit lower="-1.2" upper="1.1" effort="1000.0" velocity="0.5"/>
    </joint>

    <link name="temp2_rz">
        
    </link>

    <joint name="1_rz" type="revolute">
        <origin xyz="0 0 0" rpy="0.0 0.0 0.0"/>
        <parent link="temp2_rz"/>
        <child link="left_UpLeg_rx"/>
        <axis xyz="0.0 0.0 1.0"/>
        <limit lower="-1.5" upper="1.3" effort="1000.0" velocity="0.5"/>
    </joint>

    <link name="left_UpLeg_rx">
        <visual>
            <origin xyz="0.02136212  -0.15149257  0.00267958" rpy="0.0 0.0 0.0"/>
            <geometry>
                <mesh filename="package://Humanoid/meshes/body_parts_leftUpLeg.obj" />
            </geometry>
        </visual>
        <collision>
            <origin xyz="0.02136212 -0.15149257 0.00267958" rpy="0.0 0.0 0.0"/>
            <geometry>
                <mesh filename="package://Humanoid/meshes/body_parts_leftUpLeg.obj" />
            </geometry>
        </collision>
    </link>

    <link name="temp1_rx">
        
    </link>

    <link name="right_UpLeg_rx">
        <visual>
            <origin xyz="-0.02252603 -0.15352734 -0.00307775" rpy="0.0 0.0 0.0"/>
            <geometry>
                <mesh filename="package://Humanoid/meshes/body_parts_rightUpLeg.obj" />
            </geometry>
        </visual>
        <collision>
            <origin xyz="-0.02252603 -0.15352734 -0.00307775" rpy="0.0 0.0 0.0"/>
            <geometry>
                <mesh filename="package://Humanoid/meshes/body_parts_rightUpLeg.obj" />
            </geometry>
        </collision>
    </link>

    <joint name="2_rx" type="revolute">
        <origin xyz="-0.06767048 -0.09052169 -0.00431982" rpy="0.0 0.0 0.0"/>
        <parent link="temp1_rx"/>
        <child link="temp1_ry"/>
        <axis xyz="1.0 0.0 0.0"/>
        <limit lower="-2.2" upper="1.1" effort="1000.0" velocity="0.5"/>
    </joint>

    <link name="temp1_ry">
        
    </link>

    <joint name="2_ry" type="revolute">
        <origin xyz="0 0 0" rpy="0.0 0.0 0.0"/>
        <parent link="temp1_ry"/>
        <child link="temp1_rz"/>
        <axis xyz="0.0 1.0 0.0"/>
        <limit lower="-1.2" upper="1.1" effort="1000.0" velocity="0.5"/>
    </joint>

    <link name="temp1_rz">
        
    </link>

    <joint name="2_rz" type="revolute">
        <origin xyz="0 0 0" rpy="0.0 0.0 0.0"/>
        <parent link="temp1_rz"/>
        <child link="right_UpLeg_rx"/>
        <axis xyz="0.0 0.0 1.0"/>
        <limit lower="-1.5" upper="1.3" effort="1000.0" velocity="0.5"/>
    </joint>

    <link name="left_leg_rx">
        <visual>
            <origin xyz="-0.00726278 -0.16462932 -0.0345356" rpy="0.0 0.0 0.0"/>
            <geometry>
                <mesh filename="package://Humanoid/meshes/body_parts_leftLeg.obj" />
            </geometry>
        </visual>
        <collision>
            <origin xyz="-0.00726278 -0.16462932 -0.0345356" rpy="0.0 0.0 0.0"/>
            <geometry>
                <mesh filename="package://Humanoid/meshes/body_parts_leftLeg.obj" />
            </geometry>
        </collision>
    </link>

    <joint name="4_rx" type="revolute">
        <origin xyz="0.03427655 -0.37519857 -0.00449581" rpy="0.0 0.0 0.0"/>
        <parent link="left_UpLeg_rx"/>
        <child link="left_UpLeg_ry"/>
        <axis xyz="1.0 0.0 0.0"/>
        <limit lower="-1.2" upper="2.9" effort="1000.0" velocity="0.5"/>
    </joint>

    <link name="left_UpLeg_ry">
        
    </link>

    <joint name="4_ry" type="revolute">
        <origin xyz="0.0 0.0 0.0" rpy="0.0 0.0 0.0"/>
        <parent link="left_UpLeg_ry"/>
        <child link="left_UpLeg_rz"/>
        <axis xyz="0.0 1.0 0.0"/>
        <limit lower="-1.0" upper="1.0" effort="1000.0" velocity="0.5"/>
    </joint>

    <link name="left_UpLeg_rz">
        
    </link>

    <joint name="4_rz" type="revolute">
        <origin xyz="0.0 0.0 0.0" rpy="0.0 0.0 0.0"/>
        <parent link="left_UpLeg_rz"/>
        <child link="left_leg_rx"/>
        <axis xyz="0.0 0.0 1.0"/>
        <limit lower="-0.8" upper="0.7" effort="1000.0" velocity="0.5"/>
    </joint>

    <link name="right_leg_rx">
        <visual>
            <origin xyz="0.01018021 -0.15886355 -0.03476419" rpy="0.0 0.0 0.0"/>
            <geometry>
                <mesh filename="package://Humanoid/meshes/body_parts_rightLeg.obj" />
            </geometry>
        </visual>
        <collision>
            <origin xyz="0.01018021 -0.15886355 -0.03476419" rpy="0.0 0.0 0.0"/>
            <geometry>
                <mesh filename="package://Humanoid/meshes/body_parts_rightLeg.obj" />
            </geometry>
        </collision>
    </link>

    <joint name="5_rx" type="revolute">
        <origin xyz="-0.03829005 -0.382569 -0.00885003" rpy="0.0 0.0 0.0"/>
        <parent link="right_UpLeg_rx"/>
        <child link="right_UpLeg_ry"/>
        <axis xyz="1.0 0.0 0.0"/>
        <limit lower="-1.2" upper="2.9" effort="1000.0" velocity="0.5"/>
    </joint>

    <link name="right_UpLeg_ry">
        
    </link>

    <joint name="5_ry" type="revolute">
        <origin xyz="0.0 0.0 0.0" rpy="0.0 0.0 0.0"/>
        <parent link="right_UpLeg_ry"/>
        <child link="right_UpLeg_rz"/>
        <axis xyz="0.0 1.0 0.0"/>
        <limit lower="-1.0" upper="1.0" effort="1000.0" velocity="0.5"/>
    </joint>

    <link name="right_UpLeg_rz">
        
    </link>

    <joint name="5_rz" type="revolute">
        <origin xyz="0.0 0.0 0.0" rpy="0.0 0.0 0.0"/>
        <parent link="right_UpLeg_rz"/>
        <child link="right_leg_rx"/>
        <axis xyz="0.0 0.0 1.0"/>
        <limit lower="-0.8" upper="0.7" effort="1000.0" velocity="0.5"/>
    </joint>

    <link name="left_foot_rx">
        <visual>
            <origin xyz="0.01451171 -0.03682505 0.03742239" rpy="0.0 0.0 0.0"/>
            <geometry>
                <mesh filename="package://Humanoid/meshes/body_parts_leftFoot.obj" />
            </geometry>
        </visual>
        <collision>
            <origin xyz="0.01451171 -0.03682505 0.03742239" rpy="0.0 0.0 0.0"/>
            <geometry>
                <mesh filename="package://Humanoid/meshes/body_parts_leftFoot.obj" />
            </geometry>
        </collision>
    </link>

    <joint name="7_rx" type="revolute">
        <origin xyz="-0.0135957 -0.39796048 -0.04369333" rpy="0.0 0.0 0.0"/>
        <parent link="left_leg_rx"/>
        <child link="left_leg_ry"/>
        <axis xyz="1.0 0.0 0.0"/>
        <limit lower="-1.3" upper="1.2" effort="1000.0" velocity="0.5"/>
    </joint>

    <link name="left_leg_ry">
        
    </link>

    <joint name="7_ry" type="revolute">
        <origin xyz="0 0 0" rpy="0.0 0.0 0.0"/>
        <parent link="left_leg_ry"/>
        <child link="left_leg_rz"/>
        <axis xyz="0.0 1.0 0.0"/>
        <limit lower="-1.3" upper="1.0" effort="1000.0" velocity="0.5"/>
    </joint>

    <link name="left_leg_rz">
        
    </link>

    <joint name="7_rz" type="revolute">
        <origin xyz="0 0 0" rpy="0.0 0.0 0.0"/>
        <parent link="left_leg_rz"/>
        <child link="left_foot_rx"/>
        <axis xyz="0.0 0.0 1.0"/>
        <limit lower="-0.6" upper="1.3" effort="1000.0" velocity="0.5"/>
    </joint>

    <link name="right_foot_rx">
        <visual>
            <origin xyz="-0.01278681 -0.02989952 0.0397387" rpy="0.0 0.0 0.0"/>
            <geometry>
                <mesh filename="package://Humanoid/meshes/body_parts_rightFoot.obj" />
            </geometry>
        </visual>
        <collision>
            <origin xyz="-0.01278681 -0.02989952 0.0397387" rpy="0.0 0.0 0.0"/>
            <geometry>
                <mesh filename="package://Humanoid/meshes/body_parts_rightFoot.obj" />
            </geometry>
        </collision>
    </link>

    <joint name="8_rx" type="revolute">
        <origin xyz="0.01577377 -0.3984146 -0.0423118" rpy="0.0 0.0 0.0"/>
        <parent link="right_leg_rx"/>
        <child link="right_leg_ry"/>
        <axis xyz="1.0 0.0 0.0"/>
        <limit lower="-1.3" upper="1.2" effort="1000.0" velocity="0.5"/>
    </joint>

    <link name="right_leg_ry">
        
    </link>

    <joint name="8_ry" type="revolute">
        <origin xyz="0 0 0" rpy="0.0 0.0 0.0"/>
        <parent link="right_leg_ry"/>
        <child link="right_leg_rz"/>
        <axis xyz="0.0 1.0 0.0"/>
        <limit lower="-1.3" upper="1.0" effort="1000.0" velocity="0.5"/>
    </joint>

    <link name="right_leg_rz">
        
    </link>

    <joint name="8_rz" type="revolute">
        <origin xyz="0 0 0" rpy="0.0 0.0 0.0"/>
        <parent link="right_leg_rz"/>
        <child link="right_foot_rx"/>
        <axis xyz="0.0 0.0 1.0"/>
        <limit lower="-0.6" upper="1.3" effort="1000.0" velocity="0.5"/>
    </joint>

    <link name="left_toe">
        <visual>
            <origin xyz="-0.0072139 -0.00405795 0.02618084" rpy="0.0 0.0 0.0"/>
            <geometry>
                <mesh filename="package://Humanoid/meshes/body_parts_leftToeBase.obj" />
            </geometry>
        </visual>
        <collision>
            <origin xyz="-0.0072139 -0.00405795 0.02618084" rpy="0.0 0.0 0.0"/>
            <geometry>
                <mesh filename="package://Humanoid/meshes/body_parts_leftToeBase.obj" />
            </geometry>
        </collision>
    </link>

    <joint name="10_rx" type="revolute">
        <origin xyz="0.02635814 -0.05579078 0.1192884" rpy="0.0 0.0 0.0"/>
        <parent link="left_foot_rx"/>
        <child link="left_foot_ry"/>
        <axis xyz="1.0 0.0 0.0"/>
        <limit lower="-0.9" upper="0.3" effort="1000.0" velocity="0.5"/>
    </joint>

    <link name="left_foot_ry">
        
    </link>

    <joint name="10_ry" type="revolute">
        <origin xyz="0.0 0.0 0.0" rpy="0.0 0.0 0.0"/>
        <parent link="left_foot_ry"/>
        <child link="left_foot_rz"/>
        <axis xyz="0.0 1.0 0.0"/>
        <limit lower="-0.3" upper="0.6" effort="1000.0" velocity="0.5"/>
    </joint>

    <link name="left_foot_rz">
        
    </link>

    <joint name="10_rz" type="revolute">
        <origin xyz="0.0 0.0 0.0" rpy="0.0 0.0 0.0"/>
        <parent link="left_foot_rz"/>
        <child link="left_toe"/>
        <axis xyz="0.0 0.0 1.0"/>
        <limit lower="-0.8" upper="0.8" effort="1000.0" velocity="0.5"/>
    </joint>

    <link name="right_toe">
        <visual>
            <origin xyz="0.00808544 -0.00602809 0.02469485" rpy="0.0 0.0 0.0"/>
            <geometry>
                <mesh filename="package://Humanoid/meshes/body_parts_rightToeBase.obj" />
            </geometry>
        </visual>
        <collision>
            <origin xyz="0.00808544 -0.00602809 0.02469485" rpy="0.0 0.0 0.0"/>
            <geometry>
                <mesh filename="package://Humanoid/meshes/body_parts_rightToeBase.obj" />
            </geometry>
        </collision>
    </link>

    <joint name="11_rx" type="revolute">
        <origin xyz="-0.02537176 -0.04814398 0.12334795" rpy="0.0 0.0 0.0"/>
        <parent link="right_foot_rx"/>
        <child link="right_foot_ry"/>
        <axis xyz="1.0 0.0 0.0"/>
        <limit lower="-0.9" upper="0.3" effort="1000.0" velocity="0.5"/>
    </joint>

    <link name="right_foot_ry">
        
    </link>

    <joint name="11_ry" type="revolute">
        <origin xyz="0.0 0.0 0.0" rpy="0.0 0.0 0.0"/>
        <parent link="right_foot_ry"/>
        <child link="right_foot_rz"/>
        <axis xyz="0.0 1.0 0.0"/>
        <limit lower="-0.3" upper="0.6" effort="1000.0" velocity="0.5"/>
    </joint>

    <link name="right_foot_rz">
        
    </link>

    <joint name="11_rz" type="revolute">
        <origin xyz="0.0 0.0 0.0" rpy="0.0 0.0 0.0"/>
        <parent link="right_foot_rz"/>
        <child link="right_toe"/>
        <axis xyz="0.0 0.0 1.0"/>
        <limit lower="-0.8" upper="0.8" effort="1000.0" velocity="0.5"/>
    </joint>

    <link name="spine_rx">
        <visual>
            <origin xyz="0.0029969 0.06265952 0.02763221" rpy="0.0 0.0 0.0"/>
            <geometry>
                <mesh filename="package://Humanoid/meshes/body_parts_spine.obj" />
            </geometry>
        </visual>
        <collision>
            <origin xyz="0.0029969 0.06265952 0.02763221" rpy="0.0 0.0 0.0"/>
            <geometry>
                <mesh filename="package://Humanoid/meshes/body_parts_spine.obj" />
            </geometry>
        </collision>
    </link>
    
    <joint name="3_rx" type="revolute">
        <origin xyz="-0.00253287 0.10896324 -0.02669631" rpy="0.0 0.0 0.0"/>
        <parent link="hip_rx"/>
        <child link="hip_ry"/>
        <axis xyz="1.0 0.0 0.0"/>
        <limit lower="-0.8" upper="2.3" effort="1000.0" velocity="0.5"/>
    </joint>

    <link name="hip_ry">
        
    </link>

    <joint name="3_ry" type="revolute">
        <origin xyz="0 0 0" rpy="0.0 0.0 0.0"/>
        <parent link="hip_ry"/>
        <child link="hip_rz"/>
        <axis xyz="0.0 1.0 0.0"/>
        <limit lower="-0.7" upper="1.0" effort="1000.0" velocity="0.5"/>
    </joint>

    <link name="hip_rz">
        
    </link>

    <joint name="3_rz" type="revolute">
        <origin xyz="0 0 0" rpy="0.0 0.0 0.0"/>
        <parent link="hip_rz"/>
        <child link="spine_rx"/>
        <axis xyz="0.0 1.0 0.0"/>
        <limit lower="-0.7" upper="0.6" effort="1000.0" velocity="0.5"/>
    </joint>

    <link name="spine1_rx">
        <visual>
            <origin xyz="-0.00052418 0.02933144 0.02045965" rpy="0.0 0.0 0.0"/>
            <geometry>
                <mesh filename="package://Humanoid/meshes/body_parts_spine1.obj" />
            </geometry>
        </visual>
        <collision>
            <origin xyz="-0.00052418 0.02933144 0.02045965" rpy="0.0 0.0 0.0"/>
            <geometry>
                <mesh filename="package://Humanoid/meshes/body_parts_spine1.obj" />
            </geometry>
        </collision>
    </link>

    <joint name="6_rx" type="revolute">
        <origin xyz="0.00548704 0.13518043 0.00109247" rpy="0.0 0.0 0.0"/>
        <parent link="spine_rx"/>
        <child link="spine_ry"/>
        <axis xyz="1.0 0.0 0.0"/>
        <limit lower="-1.2" upper="1.0" effort="1000.0" velocity="0.5"/>
    </joint>

    <link name="spine_ry">
        
    </link>

    <joint name="6_ry" type="revolute">
        <origin xyz="0 0 0" rpy="0.0 0.0 0.0"/>
        <parent link="spine_ry"/>
        <child link="spine_rz"/>
        <axis xyz="0.0 1.0 0.0"/>
        <limit lower="-1.3" upper="1.0" effort="1000.0" velocity="0.5"/>
    </joint>

    <link name="spine_rz">
        
    </link>

    <joint name="6_rz" type="revolute">
        <origin xyz="0 0 0" rpy="0.0 0.0 0.0"/>
        <parent link="spine_rz"/>
        <child link="spine1_rx"/>
        <axis xyz="0.0 0.0 1.0"/>
        <limit lower="-0.5" upper="0.6" effort="1000.0" velocity="0.5"/>
    </joint>

    <link name="spine2_rx">
        <visual>
            <origin xyz="-0.0022121 0.09440039 -0.03596294" rpy="0.0 0.0 0.0"/>
            <geometry>
                <mesh filename="package://Humanoid/meshes/body_parts_spine2.obj" />
            </geometry>
        </visual>
        <collision>
            <origin xyz="-0.0022121 0.09440039 -0.03596294" rpy="0.0 0.0 0.0"/>
            <geometry>
                <mesh filename="package://Humanoid/meshes/body_parts_spine2.obj" />
            </geometry>
        </collision>
    </link>

    <link name="assist_link2">
        
    </link>

    <joint name="9_rx" type="revolute">
        <origin xyz="0.001457 0.05292223 0.02542457" rpy="0.0 0.0 0.0"/>
        <parent link="spine1_rx"/>
        <child link="spine1_ry"/>
        <axis xyz="1.0 0.0 0.0"/>
        <limit lower="-0.9" upper="1.1" effort="1000.0" velocity="0.5"/>
    </joint>

    <link name="spine1_ry">
        
    </link>

    <joint name="9_ry" type="revolute">
        <origin xyz="0 0 0" rpy="0.0 0.0 0.0"/>
        <parent link="spine1_ry"/>
        <child link="spine1_rz"/>
        <axis xyz="0.0 1.0 0.0"/>
        <limit lower="-0.7" upper="0.6" effort="1000.0" velocity="0.5"/>
    </joint>

    <link name="spine1_rz">
        
    </link>

    <joint name="9_rz" type="revolute">
        <origin xyz="0 0 0" rpy="0.0 0.0 0.0"/>
        <parent link="spine1_rz"/>
        <child link="assist_link2"/>
        <axis xyz="0.0 0.0 1.0"/>
        <limit lower="-0.4" upper="0.4" effort="1000.0" velocity="0.5"/>
    </joint>

    <joint name="assist_B1" type="fixed">
        <origin xyz="0.0 0.0 0.0" rpy="0.0 0.0 0.0"/>
        <parent link="assist_link2"/>
        <child link="temp14_rx"/>
        <axis xyz="0.0 0.0 0.0"/>
        <limit lower="0.0" upper="0.0" effort="0.0" velocity="0.0"/>
    </joint>

     <joint name="assist_B2" type="fixed">
        <origin xyz="0.0 0.0 0.0" rpy="0.0 0.0 0.0"/>
        <parent link="assist_link2"/>
        <child link="spine2_rx"/>
        <axis xyz="0.0 0.0 0.0"/>
        <limit lower="0.0" upper="0.0" effort="0.0" velocity="0.0"/>
    </joint>

     <joint name="assist_B3" type="fixed">
        <origin xyz="0.0 0.0 0.0" rpy="0.0 0.0 0.0"/>
        <parent link="assist_link2"/>
        <child link="temp13_rx"/>
        <axis xyz="0.0 0.0 0.0"/>
        <limit lower="0.0" upper="0.0" effort="0.0" velocity="0.0"/>
    </joint>
    

    <link name="neck_rx">
        <visual>
            <origin xyz="0.00058504 0.03762274 0.01938053" rpy="0.0 0.0 0.0"/>
            <geometry>
                <mesh filename="package://Humanoid/meshes/body_parts_neck.obj" />
            </geometry>
        </visual>
        <collision>
            <origin xyz="0.00058504 0.03762274 0.01938053" rpy="0.0 0.0 0.0"/>
            <geometry>
                <mesh filename="package://Humanoid/meshes/body_parts_neck.obj" />
            </geometry>
        </collision>
    </link>

    <joint name="12_rx" type="revolute">
        <origin xyz="-0.00277839 0.21387038 -0.04285703" rpy="0.0 0.0 0.0"/>
        <parent link="spine2_rx"/>
        <child link="spine2_ry"/>
        <axis xyz="1.0 0.0 0.0"/>
        <limit lower="-1.5" upper="2.0" effort="1000.0" velocity="0.5"/>
    </joint>

    <link name="spine2_ry">
        
    </link>

    <joint name="12_ry" type="revolute">
        <origin xyz="0 0 0" rpy="0.0 0.0 0.0"/>
        <parent link="spine2_ry"/>
        <child link="spine2_rz"/>
        <axis xyz="0.0 1.0 0.0"/>
        <limit lower="-1.0" upper="1.0" effort="1000.0" velocity="0.5"/>
    </joint>

    <link name="spine2_rz">
        
    </link>

    <joint name="12_rz" type="revolute">
        <origin xyz="0 0 0" rpy="0.0 0.0 0.0"/>
        <parent link="spine2_rz"/>
        <child link="neck_rx"/>
        <axis xyz="0.0 0.0 1.0"/>
        <limit lower="-0.7" upper="0.7" effort="1000.0" velocity="0.5"/>
    </joint>

    <link name="head">
        <visual>
            <origin xyz="-0.00434165 0.0912436 -0.0164248" rpy="0.0 0.0 0.0"/>
            <geometry>
                <mesh filename="package://Humanoid/meshes/body_parts_head.obj" />
            </geometry>
        </visual>
        <collision>
            <origin xyz="-0.00434165 0.0912436 -0.0164248" rpy="0.0 0.0 0.0"/>
            <geometry>
                <mesh filename="package://Humanoid/meshes/body_parts_head.obj" />
            </geometry>
        </collision>
    </link>

    <joint name="15_rx" type="revolute">
        <origin xyz="0.00515184 0.06496963 0.05134897" rpy="0.0 0.0 0.0"/>
        <parent link="neck_rx"/>
        <child link="neck_ry"/>
        <axis xyz="1.0 0.0 0.0"/>
        <limit lower="-1.4" upper="1.8" effort="1000.0" velocity="0.5"/>
    </joint>

    <link name="neck_ry">
        
    </link>

    <joint name="15_ry" type="revolute">
        <origin xyz="0 0 0" rpy="0.0 0.0 0.0"/>
        <parent link="neck_ry"/>
        <child link="neck_rz"/>
        <axis xyz="0.0 1.0 0.0"/>
        <limit lower="-1.3" upper="1.0" effort="1000.0" velocity="0.5"/>
    </joint>

    <link name="neck_rz">
        
    </link>

    <joint name="15_rz" type="revolute">
        <origin xyz="0 0 0" rpy="0.0 0.0 0.0"/>
        <parent link="neck_rz"/>
        <child link="head"/>
        <axis xyz="0.0 0.0 1.0"/>
        <limit lower="-0.9" upper="1.6" effort="1000.0" velocity="0.5"/>
    </joint>

    <link name="temp14_rx">
    </link>

    <joint name="13_rx" type="revolute">
        <origin xyz="0.07884474 0.12174932 -0.03408961" rpy="0.0 0.0 0.0"/>
        <parent link="temp14_rx"/>
        <child link="temp14_ry"/>
        <axis xyz="1.0 0.0 0.0"/>
        <limit lower="-1.3" upper="1.7" effort="1000.0" velocity="0.5"/>
    </joint>

    <link name="temp14_ry">
        
    </link>

    <joint name="13_ry" type="revolute">
        <origin xyz="0 0 0" rpy="0.0 0.0 0.0"/>
        <parent link="temp14_ry"/>
        <child link="temp14_rz"/>
        <axis xyz="0.0 1.0 0.0"/>
        <limit lower="-0.9" upper="1.0" effort="1000.0" velocity="0.5"/>
    </joint>

    <link name="temp14_rz">
        
    </link>

    <joint name="13_rz" type="revolute">
        <origin xyz="0 0 0" rpy="0.0 0.0 0.0"/>
        <parent link="temp14_rz"/>
        <child link="left_shoulder_rx"/>
        <axis xyz="0.0 0.0 1.0"/>
        <limit lower="-1.3" upper="1.2" effort="1000.0" velocity="0.5"/>
    </joint>    

    <link name="temp13_rx">
    </link>

    <joint name="14_rx" type="revolute">
        <origin xyz="-0.08175919 0.11883285 -0.03861528" rpy="0.0 0.0 0.0"/>
        <parent link="temp13_rx"/>
        <child link="temp13_ry"/>
        <axis xyz="1.0 0.0 0.0"/>
        <limit lower="-1.3" upper="1.7" effort="1000.0" velocity="0.5"/>
    </joint>

    <link name="temp13_ry">
        
    </link>

    <joint name="14_ry" type="revolute">
        <origin xyz="0 0 0" rpy="0.0 0.0 0.0"/>
        <parent link="temp13_ry"/>
        <child link="temp13_rz"/>
        <axis xyz="0.0 1.0 0.0"/>
        <limit lower="-0.9" upper="1.0" effort="1000.0" velocity="0.5"/>
    </joint>    

    <link name="temp13_rz">
        
    </link>

    <joint name="14_rz" type="revolute">
        <origin xyz="0 0 0" rpy="0.0 0.0 0.0"/>
        <parent link="temp13_rz"/>
        <child link="right_shoulder_rx"/>
        <axis xyz="0.0 0.0 1.0"/>
        <limit lower="-1.3" upper="1.2" effort="1000.0" velocity="0.5"/>
    </joint> 

    <link name="left_shoulder_rx">
        <visual>
            <origin xyz="0.06559623 0.02613187 -0.02027318" rpy="0.0 0.0 0.0"/>
            <geometry>
                <mesh filename="package://Humanoid/meshes/body_parts_leftShoulder.obj" />
            </geometry>
        </visual>
        <collision>
            <origin xyz="0.06559623 0.02613187 -0.02027318" rpy="0.0 0.0 0.0"/>
            <geometry>
                <mesh filename="package://Humanoid/meshes/body_parts_leftShoulder.obj" />
            </geometry>
        </collision>
    </link>

    <link name="right_shoulder_rx">
        <visual>
            <origin xyz="-0.0667859 0.02682777 -0.01567558" rpy="0.0 0.0 0.0"/>
            <geometry>
                <mesh filename="package://Humanoid/meshes/body_parts_rightShoulder.obj" />
            </geometry>
        </visual>
        <collision>
            <origin xyz="-0.0667859 0.02682777 -0.01567558" rpy="0.0 0.0 0.0"/>
            <geometry>
                <mesh filename="package://Humanoid/meshes/body_parts_rightShoulder.obj" />
            </geometry>
        </collision>
    </link>

    <joint name="16_rx" type="revolute">
        <origin xyz="0.09097692 0.03046888 -0.00886815" rpy="0.0 0.0 0.0"/>
        <parent link="left_shoulder_rx"/>
        <child link="left_shoulder_ry"/>
        <axis xyz="1.0 0.0 0.0"/>
        <limit lower="-3.1" upper="3.1" effort="1000.0" velocity="0.5"/>
    </joint>

    <link name="left_shoulder_ry">
        
    </link>

    <joint name="16_ry" type="revolute">
        <origin xyz="0 0 0" rpy="0.0 0.0 0.0"/>
        <parent link="left_shoulder_ry"/>
        <child link="left_shoulder_rz"/>
        <axis xyz="0.0 1.0 0.0"/>
        <limit lower="-1.3" upper="1.3" effort="1000.0" velocity="0.5"/>
    </joint>

    <link name="left_shoulder_rz">
        
    </link>

    <joint name="16_rz" type="revolute">
        <origin xyz="0 0 0" rpy="0.0 0.0 0.0"/>
        <parent link="left_shoulder_rz"/>
        <child link="left_arm_rx"/>
        <axis xyz="0.0 0.0 1.0"/>
        <limit lower="-3.1" upper="3.1" effort="1000.0" velocity="0.5"/>
    </joint>

    <link name="left_arm_rx">
        <visual>
            <origin xyz="0.12948829 -0.01228957 -0.0090026" rpy="0.0 0.0 0.0"/>
            <geometry>
                <mesh filename="package://Humanoid/meshes/body_parts_leftArm.obj" />
            </geometry>
        </visual>
        <collision>
            <origin xyz="0.12948829 -0.01228957 -0.0090026" rpy="0.0 0.0 0.0"/>
            <geometry>
                <mesh filename="package://Humanoid/meshes/body_parts_leftArm.obj" />
            </geometry>
        </collision>
    </link>

    <joint name="18_rx" type="revolute">
        <origin xyz="0.2596122 -0.01277207 -0.02745643" rpy="0.0 0.0 0.0"/>
        <parent link="left_arm_rx"/>
        <child link="left_arm_ry"/>
        <axis xyz="1.0 0.0 0.0"/>
        <limit lower="-3.14" upper="3.14" effort="1000.0" velocity="0.5"/>
    </joint>

    <link name="left_arm_ry">
        
    </link>

    <joint name="18_ry" type="revolute">
        <origin xyz="0 0 0" rpy="0.0 0.0 0.0"/>
        <parent link="left_arm_ry"/>
        <child link="left_arm_rz"/>
        <axis xyz="0.0 1.0 0.0"/>
        <limit lower="-1.57" upper="0.8" effort="1000.0" velocity="0.5"/>
    </joint>

    <link name="left_arm_rz">
        
    </link>

    <joint name="18_rz" type="revolute">
        <origin xyz="0 0 0" rpy="0.0 0.0 0.0"/>
        <parent link="left_arm_rz"/>
        <child link="left_fore_arm_rx"/>
        <axis xyz="0.0 0.0 1.0"/>
        <limit lower="-3.14" upper="3.14" effort="1000.0" velocity="0.5"/>
    </joint>

    <link name="left_fore_arm_rx">
        <visual>
            <origin xyz="0.10665728 0.00690599 0.00605961" rpy="0.0 0.0 0.0"/>
            <geometry>
                <mesh filename="package://Humanoid/meshes/body_parts_leftForeArm.obj" />
            </geometry>
        </visual>
        <collision>
            <origin xyz="0.10665728 0.00690599 0.00605961" rpy="0.0 0.0 0.0"/>
            <geometry>
                <mesh filename="package://Humanoid/meshes/body_parts_leftForeArm.obj" />
            </geometry>
        </collision>
    </link>

    <joint name="20_rx" type="revolute">
        <origin xyz="0.2492336 0.00898604 -0.00117092" rpy="0.0 0.0 0.0"/>
        <parent link="left_fore_arm_rx"/>
        <child link="left_fore_arm_ry"/>
        <axis xyz="1.0 0.0 0.0"/>
        <limit lower="-3.14" upper="3.1" effort="1000.0" velocity="0.5"/>
    </joint>

    <link name="left_fore_arm_ry">
        
    </link>

    <joint name="20_ry" type="revolute">
        <origin xyz="0 0 0" rpy="0.0 0.0 0.0"/>
        <parent link="left_fore_arm_ry"/>
        <child link="left_fore_arm_rz"/>
        <axis xyz="0.0 1.0 0.0"/>
        <limit lower="-1.57" upper="1.3" effort="1000.0" velocity="0.5"/>
    </joint>

    <link name="left_fore_arm_rz">
        
    </link>

    <joint name="20_rz" type="revolute">
        <origin xyz="0 0 0" rpy="0.0 0.0 0.0"/>
        <parent link="left_fore_arm_rz"/>
        <child link="left_hand"/>
        <axis xyz="0.0 0.0 1.0"/>
        <limit lower="-3.14" upper="3.1" effort="1000.0" velocity="0.5"/>
    </joint>

    <link name="left_hand">
        <visual>
            <origin xyz="0.08488861 -0.00938576 0.00616219" rpy="0.0 0.0 0.0"/>
            <geometry>
                <mesh filename="package://Humanoid/meshes/body_parts_leftHand.obj" />
            </geometry>
        </visual>
        <collision>
            <origin xyz="0.08488861 -0.00938576 0.00616219" rpy="0.0 0.0 0.0"/>
            <geometry>
                <mesh filename="package://Humanoid/meshes/body_parts_leftHand.obj" />
            </geometry>
        </collision>
    </link>

    <joint name="17_rx" type="revolute">
        <origin xyz="-0.09601238 0.03255117 -0.00914307" rpy="0.0 0.0 0.0"/>
        <parent link="right_shoulder_rx"/>
        <child link="right_shoulder_ry"/>
        <axis xyz="1.0 0.0 0.0"/>
        <limit lower="-3.1" upper="3.1" effort="1000.0" velocity="0.5"/>
    </joint>

    <link name="right_shoulder_ry">
        
    </link>

    <joint name="17_ry" type="revolute">
        <origin xyz="0 0 0" rpy="0.0 0.0 0.0"/>
        <parent link="right_shoulder_ry"/>
        <child link="right_shoulder_rz"/>
        <axis xyz="0.0 1.0 0.0"/>
        <limit lower="-1.3" upper="1.3" effort="1000.0" velocity="0.5"/>
    </joint>

    <link name="right_shoulder_rz">
        
    </link>

    <joint name="17_rz" type="revolute">
        <origin xyz="0 0 0" rpy="0.0 0.0 0.0"/>
        <parent link="right_shoulder_rz"/>
        <child link="right_arm_rx"/>
        <axis xyz="0.0 0.0 1.0"/>
        <limit lower="-3.1" upper="3.1" effort="1000.0" velocity="0.5"/>
    </joint>

    <link name="right_arm_rx">
        <visual>
            <origin xyz="-0.12550239 -0.01296561 -0.00590812" rpy="0.0 0.0 0.0"/>
            <geometry>
                <mesh filename="package://Humanoid/meshes/body_parts_rightArm.obj" />
            </geometry>
        </visual>
        <collision>
            <origin xyz="-0.12550239 -0.01296561 -0.00590812" rpy="0.0 0.0 0.0"/>
            <geometry>
                <mesh filename="package://Humanoid/meshes/body_parts_rightArm.obj" />
            </geometry>
        </collision>
    </link>

    <joint name="19_rx" type="revolute">
        <origin xyz="-0.25374195 -0.01332924 -0.02140098" rpy="0.0 0.0 0.0"/>
        <parent link="right_arm_rx"/>
        <child link="right_arm_ry"/>
        <axis xyz="1.0 0.0 0.0"/>
        <limit lower="-3.14" upper="3.14" effort="1000.0" velocity="0.5"/>
    </joint>

    <link name="right_arm_ry">
        
    </link>

    <joint name="19_ry" type="revolute">
        <origin xyz="0 0 0" rpy="0.0 0.0 0.0"/>
        <parent link="right_arm_ry"/>
        <child link="right_arm_rz"/>
        <axis xyz="0.0 1.0 0.0"/>
        <limit lower="-1.57" upper="0.8" effort="1000.0" velocity="0.5"/>
    </joint>

    <link name="right_arm_rz">
        
    </link>

    <joint name="19_rz" type="revolute">
        <origin xyz="0 0 0" rpy="0.0 0.0 0.0"/>
        <parent link="right_arm_rz"/>
        <child link="right_fore_arm_rx"/>
        <axis xyz="0.0 0.0 1.0"/>
        <limit lower="-3.14" upper="3.14" effort="1000.0" velocity="0.5"/>
    </joint>

    <link name="right_fore_arm_rx">
        <visual>
            <origin xyz="-0.10992141 0.00679169 0.00313351" rpy="0.0 0.0 0.0"/>
            <geometry>
                <mesh filename="package://Humanoid/meshes/body_parts_rightForeArm.obj" />
            </geometry>
        </visual>
        <collision>
            <origin xyz="-0.10992141 0.00679169 0.00313351" rpy="0.0 0.0 0.0"/>
            <geometry>
                <mesh filename="package://Humanoid/meshes/body_parts_rightForeArm.obj" />
            </geometry>
        </collision>
    </link>

    <joint name="21_rx" type="revolute">
        <origin xyz="-0.2552981 0.0077723 -0.0055592" rpy="0.0 0.0 0.0"/>
        <parent link="right_fore_arm_rx"/>
        <child link="right_fore_arm_ry"/>
        <axis xyz="1.0 0.0 0.0"/>
        <limit lower="-3.14" upper="3.1" effort="1000.0" velocity="0.5"/>
    </joint>

    <link name="right_fore_arm_ry">
        
    </link>

    <joint name="21_ry" type="revolute">
        <origin xyz="0 0 0" rpy="0.0 0.0 0.0"/>
        <parent link="right_fore_arm_ry"/>
        <child link="right_fore_arm_rz"/>
        <axis xyz="0.0 1.0 0.0"/>
        <limit lower="-1.57" upper="1.3" effort="1000.0" velocity="0.5"/>
    </joint>

    <link name="right_fore_arm_rz">
        
    </link>

    <joint name="21_rz" type="revolute">
        <origin xyz="0 0 0" rpy="0.0 0.0 0.0"/>
        <parent link="right_fore_arm_rz"/>
        <child link="right_hand"/>
        <axis xyz="0.0 0.0 1.0"/>
        <limit lower="-3.14" upper="3.1" effort="1000.0" velocity="0.5"/>
    </joint>

    <link name="right_hand">
        <visual>
            <origin xyz="-0.08138476 -0.00979895 0.0080402" rpy="0.0 0.0 0.0"/>
            <geometry>
                <mesh filename="package://Humanoid/meshes/body_parts_rightHand.obj" />
            </geometry>
        </visual>
        <collision>
            <origin xyz="-0.08138476 -0.00979895 0.0080402" rpy="0.0 0.0 0.0"/>
            <geometry>
                <mesh filename="package://Humanoid/meshes/body_parts_rightHand.obj" />
            </geometry>
        </collision>
    </link>

</robot>