<robot name="dumpUrdf">
	<link name = "base">
		<inertial>
			<origin rpy = "0 0 0"  xyz = "0 0 0" />
			<mass value =  "0.0001" />
			<inertia ixx = "0.0001" ixy = "0" ixz = "0" iyy = "0.0001" iyz = "0" izz = "0.0001" />
		</inertial>
	</link>
	<link name = "root">
		<inertial>
			<origin rpy = "0 0 0"  xyz = "0 0 0" />
			<mass value =  "15" />
			<inertia ixx = "0.1" ixy = "0" ixz = "0" iyy = "0.1" iyz = "0" izz = "0.1" />
		</inertial>
		<collision>
			<origin rpy = "0 0 0"  xyz = "0 0 0" />
			<geometry>
				<sphere radius="0.07" />
			</geometry>
		</collision>
	</link>
	<joint name="root" type="floating">
		<parent link = "base" />
		<child link = "root" />
		<origin rpy = "0 0 0  " xyz ="0 0 0"  />
	</joint>
	<link name = "root_dammy_ori">
		<inertial>
			<origin rpy = "0 0 0"  xyz = "-0.00179506 -0.22333345 0.02821913" />
			<mass value =  "0.00001" />
			<inertia ixx = "0.1" ixy = "0" ixz = "0" iyy = "0.1" iyz = "0" izz = "0.1" />
		</inertial>
		<collision>
			<origin rpy = "0 0 0"  xyz = "0 0 0" />
			<geometry>
				<sphere radius="0.00000004" />
			</geometry>
		</collision>
	</link>
	<joint name="root_dammy_ori" type="fixed">
		<parent link = "root" />
		<child link = "root_dammy_ori" />
		<origin rpy = "-1.57 -1.57 0 " xyz ="-1.79505907e-03 -2.23333448e-01 2.82191262e-02"  />
	</joint>
	<link name = "left_hip_rx">
		<inertial>
			<origin rpy = "0 0 0"  xyz = "0.06951974 -0.09140623 -0.00681533" />
			<mass value =  "1e-05" />
			<inertia ixx = "0.1" ixy = "0" ixz = "0" iyy = "0.1" iyz = "0" izz = "0.1" />
		</inertial>
		<collision>
			<origin rpy = "0 0 0"  xyz = "0.06951974 -0.09140623 -0.00681533" />
			<geometry>
				<mesh filename="package://Humanoid/meshes/body_parts_hips.stl" />
			</geometry>
		</collision>
	</link>
	<joint name="left_hip_rx" type="revolute">
		<parent link = "root_dammy_ori" />
		<child link = "left_hip_rx" />
		<limit effort="1000.0" lower= "-2.5" upper= "1.4" velocity="0.5" />
		<origin rpy = "0 0 0" xyz ="6.77246749e-02 -3.14739674e-01 2.14037914e-02"  />
		<axis xyz = "0.0 1.0 0.0" />
	</joint>
	<link name = "left_hip_ry">
		<inertial>
			<origin rpy = "0 0 0"  xyz = "0.00764 0.06 0.0670" />
			<mass value =  "1e-05" />
			<inertia ixx = "0.1" ixy = "0" ixz = "0" iyy = "0.1" iyz = "0" izz = "0.1" />
		</inertial>
		<collision>
			<origin rpy = "0 0 0 "  xyz = "0.00764 0.06 0.0670" />
			<geometry>
				<sphere radius="0.000001" />
			</geometry>
		</collision>
	</link>
	<joint name="left_hip_ry" type="revolute">
		<parent link = "left_hip_rx" />
		<child link = "left_hip_ry" />
		<limit effort="1000.0" lower= "-0.6" upper= "0.6" velocity="0.5" />
		<origin rpy = "0 0 0" xyz ="0 0 0"  />
		<axis xyz = "0.0 0.0 1.0" />
	</joint>
	<link name = "left_hip_rz">
		<inertial>
			<origin rpy = "0 0 0"  xyz = "0 0 0" />
			<mass value =  "1e-05" />
			<inertia ixx = "0.1" ixy = "0" ixz = "0" iyy = "0.1" iyz = "0" izz = "0.1" />
		</inertial>
		<collision>
			<origin rpy = "0 0 0"  xyz = "0 0 0" />
			<geometry>
				<sphere radius="1e-06" />
			</geometry>
		</collision>
	</link>
	<joint name="left_hip_rz" type="revolute">
		<parent link = "left_hip_ry" />
		<child link = "left_hip_rz" />
		<limit effort="1000.0" lower= "-0.8" upper= "1.4" velocity="0.5" />
		<origin rpy = "0 0 0" xyz ="0 0 0"  />
		<axis xyz = "1.0 0.0 0.0" />
	</joint>
	<link name = "right_hip_rx">
		<inertial>
			<origin rpy = "0 0 0"  xyz = "-0.06767048 -0.09052169 -0.00431982" />
			<mass value =  "1e-05" />
			<inertia ixx = "0.1" ixy = "0" ixz = "0" iyy = "0.1" iyz = "0" izz = "0.1" />
		</inertial>
		<collision>
			<origin rpy = "0 0 0"  xyz = "-0.06767048 -0.09052169 -0.00431982" />
			<geometry>
				<mesh filename="package://Humanoid/meshes/body_parts_hips.stl" />
			</geometry>
		</collision>
	</link>
	<joint name="right_hip_rx" type="revolute">
		<parent link = "root_dammy_ori" />
		<child link = "right_hip_rx" />
		<limit effort="1000.0" lower= "-2.5" upper= "1.4" velocity="0.5" />
		<origin rpy = "0 0 0" xyz ="-6.94655403e-02 -3.13855141e-01 2.38993075e-02"  />
		<axis xyz = "0.0 1.0 0.0" />
	</joint>
	<link name = "right_hip_ry">
		<inertial>
			<origin rpy = "0 0 0"  xyz = "0.002809   -0.068214   0.066" />
			<mass value =  "1e-05" />
			<inertia ixx = "0.1" ixy = "0" ixz = "0" iyy = "0.1" iyz = "0" izz = "0.1" />
		</inertial>
		<collision>
			<origin rpy = "0 0 0"  xyz = "0.002809   -0.068214   0.066" />
			<geometry>
				<sphere radius="0.000001" />
			</geometry>
		</collision>
	</link>
	<joint name="right_hip_ry" type="revolute">
		<parent link = "right_hip_rx" />
		<child link = "right_hip_ry" />
		<limit effort="1000.0" lower= "-0.6" upper= "0.6" velocity="0.5" />
		<origin rpy = "0 0 0" xyz ="0 0 0"  />
		<axis xyz = "0.0 0.0 1.0" />
	</joint>
	<link name = "right_hip_rz">
		<inertial>
			<origin rpy = "0 0 0"  xyz = "0 0 0" />
			<mass value =  "1e-05" />
			<inertia ixx = "0.1" ixy = "0" ixz = "0" iyy = "0.1" iyz = "0" izz = "0.1" />
		</inertial>
		<collision>
			<origin rpy = "0 0 0"  xyz = "0 0 0" />
			<geometry>
				<sphere radius="1e-05" />
			</geometry>
		</collision>
	</link>
	<joint name="right_hip_rz" type="revolute">
		<parent link = "right_hip_ry" />
		<child link = "right_hip_rz" />
		<limit effort="1000.0" lower= "-1.4" upper= "0.8" velocity="0.5" />
		<origin rpy = "0 0 0" xyz ="0 0 0"  />
		<axis xyz = "1.0 0.0 0.0" />
	</joint>
	<link name = "spine_2_limb">
		<inertial>
			<origin rpy = "0 0 0"  xyz = "-0.00253287 0.10896324 -0.02669631" />
			<mass value =  "2" />
			<inertia ixx = "0.1" ixy = "0" ixz = "0" iyy = "0.1" iyz = "0" izz = "0.1" />
		</inertial>
		<collision>
			<origin rpy = "0 0 0"  xyz = "-0.00253287 0.10896324 -0.02669631" />
			<geometry>
				<mesh filename="package://Humanoid/meshes/body_parts_spine.stl" />
			</geometry>
		</collision>
	</link>
	<joint name="rootdammy" type="fixed">
		<parent link = "root_dammy_ori" />
		<child link = "spine_2_limb" />
		<origin rpy = "0 0 0" xyz ="0 0 0"  />
	</joint>
	<link name = "spine_2_rx">
		<inertial>
			<origin rpy = "0 0 0"  xyz = "0 0 0" />
			<mass value =  "1e-05" />
			<inertia ixx = "0.1" ixy = "0" ixz = "0" iyy = "0.1" iyz = "0" izz = "0.1" />
		</inertial>
		<collision>
			<origin rpy = "0 0 0"  xyz = "0 0 0" />
			<geometry>
				<sphere radius="1e-06" />
			</geometry>
		</collision>
	</link>
	<joint name="spine_2_rx" type="fixed">
		<parent link = "spine_2_limb" />
		<child link = "spine_2_rx" />
		<origin rpy = "0 0 0" xyz ="-4.32793330e-03 -1.14370212e-01 1.52281299e-03"  />
	</joint>
	<link name = "spine_2_ry">
		<inertial>
			<origin rpy = "0 0 0"  xyz = "0 0 0" />
			<mass value =  "1e-05" />
			<inertia ixx = "0.1" ixy = "0" ixz = "0" iyy = "0.1" iyz = "0" izz = "0.1" />
		</inertial>
		<collision>
			<origin rpy = "0 0 0"  xyz = "0 0 0" />
			<geometry>
				<sphere radius="1e-06" />
			</geometry>
		</collision>
	</link>
	<joint name="spine_2_ry" type="fixed">
		<parent link = "spine_2_rx" />
		<child link = "spine_2_ry" />
		<origin rpy = "0 0 0" xyz ="0 0 0"  />
	</joint>
	<link name = "spine_2_rz">
		<inertial>
			<origin rpy = "0 0 0"  xyz = "0 0 0" />
			<mass value =  "1e-05" />
			<inertia ixx = "0.1" ixy = "0" ixz = "0" iyy = "0.1" iyz = "0" izz = "0.1" />
		</inertial>
		<collision>
			<origin rpy = "0 0 0"  xyz = "0 0 0" />
			<geometry>
				<sphere radius="1e-05" />
			</geometry>
		</collision>
	</link>
	<joint name="spine_2_rz" type="fixed">
		<parent link = "spine_2_ry" />
		<child link = "spine_2_rz" />
		<origin rpy = "0 0 0" xyz ="0 0 0"  />
	</joint>
	<link name = "left_knee_limb">
		<inertial>
			<origin rpy = "0 0 0"  xyz = "0.03427655 -0.37519857 -0.00449581" />
			<mass value =  "2" />
			<inertia ixx = "0.1" ixy = "0" ixz = "0" iyy = "0.1" iyz = "0" izz = "0.1" />
		</inertial>
		<collision>
			<origin rpy = "0 0 0"  xyz = "0.03427655 -0.37519857 -0.00449581" />
			<geometry>
				<mesh filename="package://Humanoid/meshes/body_parts_leftUpLeg.stl" />
			</geometry>
		</collision>
	</link>
	<joint name="left_hip_rzdammy" type="fixed">
		<parent link = "left_hip_rz" />
		<child link = "left_knee_limb" />
		<origin rpy = "0 0 0" xyz ="0 0 0"  />
	</joint>
	<link name = "left_knee_rx">
		<inertial>
			<origin rpy = "0 0 0"  xyz = "0 0 0" />
			<mass value =  "1e-05" />
			<inertia ixx = "0.1" ixy = "0" ixz = "0" iyy = "0.1" iyz = "0" izz = "0.1" />
		</inertial>
		<collision>
			<origin rpy = "0 0 0"  xyz = "0 0 0" />
			<geometry>
				<sphere radius="1e-06" />
			</geometry>
		</collision>
	</link>
	<joint name="left_knee_rx" type="revolute">
		<parent link = "left_knee_limb" />
		<child link = "left_knee_rx" />
		<limit effort="1000.0" lower= "-0.1" upper= "2.5" velocity="0.5" />
		<origin rpy = "0 0 0" xyz ="1.02001220e-01 -6.89938247e-01 1.69079844e-02"  />
		<axis xyz = "0.0 1.0 0.0" />
	</joint>
	<link name = "left_knee_ry">
		<inertial>
			<origin rpy = "0 0 0"  xyz = "0 0 0" />
			<mass value =  "1e-05" />
			<inertia ixx = "0.1" ixy = "0" ixz = "0" iyy = "0.1" iyz = "0" izz = "0.1" />
		</inertial>
		<collision>
			<origin rpy = "0 0 0"  xyz = "0 0 0" />
			<geometry>
				<sphere radius="1e-06" />
			</geometry>
		</collision>
	</link>
	<joint name="left_knee_ry" type="fixed">
		<parent link = "left_knee_rx" />
		<child link = "left_knee_ry" />
		<origin rpy = "0 0 0" xyz ="0 0 0"  />
	</joint>
	<link name = "left_knee_rz">
		<inertial>
			<origin rpy = "0 0 0"  xyz = "0 0 0" />
			<mass value =  "1e-05" />
			<inertia ixx = "0.1" ixy = "0" ixz = "0" iyy = "0.1" iyz = "0" izz = "0.1" />
		</inertial>
		<collision>
			<origin rpy = "0 0 0"  xyz = "0 0 0" />
			<geometry>
				<sphere radius="1e-05" />
			</geometry>
		</collision>
	</link>
	<joint name="left_knee_rz" type="fixed">
		<parent link = "left_knee_ry" />
		<child link = "left_knee_rz" />
		<origin rpy = "0 0 0" xyz ="0 0 0"  />
	</joint>
	<link name = "right_knee_limb">
		<inertial>
			<origin rpy = "0 0 0"  xyz = "-0.03829005 -0.382569 -0.00885003" />
			<mass value =  "2" />
			<inertia ixx = "0.1" ixy = "0" ixz = "0" iyy = "0.1" iyz = "0" izz = "0.1" />
		</inertial>
		<collision>
			<origin rpy = "0 0 0"  xyz = "-0.03829005 -0.382569 -0.00885003" />
			<geometry>
				<mesh filename="package://Humanoid/meshes/body_parts_leftUpLeg.stl" />
			</geometry>
		</collision>
	</link>
	<joint name="right_hip_rzdammy" type="fixed">
		<parent link = "right_hip_rz" />
		<child link = "right_knee_limb" />
		<origin rpy = "0 0 0" xyz ="0 0 0"  />
	</joint>
	<link name = "right_knee_rx">
		<inertial>
			<origin rpy = "0 0 0"  xyz = "0 0 0" />
			<mass value =  "1e-05" />
			<inertia ixx = "0.1" ixy = "0" ixz = "0" iyy = "0.1" iyz = "0" izz = "0.1" />
		</inertial>
		<collision>
			<origin rpy = "0 0 0"  xyz = "0 0 0" />
			<geometry>
				<sphere radius="1e-06" />
			</geometry>
		</collision>
	</link>
	<joint name="right_knee_rx" type="revolute">
		<parent link = "right_knee_limb" />
		<child link = "right_knee_rx" />
		<limit effort="1000.0" lower= "-0.1" upper= "2.5" velocity="0.5" />
		<origin rpy = "0 0 0" xyz ="-1.07755594e-01 -6.96424127e-01 1.50492759e-02"  />
		<axis xyz = "0.0 1.0 0.0" />
	</joint>
	<link name = "right_knee_ry">
		<inertial>
			<origin rpy = "0 0 0"  xyz = "0 0 0" />
			<mass value =  "1e-05" />
			<inertia ixx = "0.1" ixy = "0" ixz = "0" iyy = "0.1" iyz = "0" izz = "0.1" />
		</inertial>
		<collision>
			<origin rpy = "0 0 0"  xyz = "0 0 0" />
			<geometry>
				<sphere radius="1e-06" />
			</geometry>
		</collision>
	</link>
	<joint name="right_knee_ry" type="fixed">
		<parent link = "right_knee_rx" />
		<child link = "right_knee_ry" />
		<origin rpy = "0 0 0" xyz ="0 0 0"  />
	</joint>
	<link name = "right_knee_rz">
		<inertial>
			<origin rpy = "0 0 0"  xyz = "0 0 0" />
			<mass value =  "1e-05" />
			<inertia ixx = "0.1" ixy = "0" ixz = "0" iyy = "0.1" iyz = "0" izz = "0.1" />
		</inertial>
		<collision>
			<origin rpy = "0 0 0"  xyz = "0 0 0" />
			<geometry>
				<sphere radius="1e-05" />
			</geometry>
		</collision>
	</link>
	<joint name="right_knee_rz" type="fixed">
		<parent link = "right_knee_ry" />
		<child link = "right_knee_rz" />
		<origin rpy = "0 0 0" xyz ="0 0 0"  />
	</joint>
	<link name = "spine_3_limb">
		<inertial>
			<origin rpy = "0 0 0"  xyz = "0.00548704 0.13518043 0.00109247" />
			<mass value =  "2" />
			<inertia ixx = "0.1" ixy = "0" ixz = "0" iyy = "0.1" iyz = "0" izz = "0.1" />
		</inertial>
		<collision>
			<origin rpy = "0 0 0"  xyz = "0.00548704 0.13518043 0.00109247" />
			<geometry>
				<mesh filename="package://Humanoid/meshes/body_parts_spine1.stl" />
			</geometry>
		</collision>
	</link>
	<joint name="spine_2_rzdammy" type="fixed">
		<parent link = "spine_2_rz" />
		<child link = "spine_3_limb" />
		<origin rpy = "0 0 0" xyz ="0 0 0"  />
	</joint>
	<link name = "spine_3_rx">
		<inertial>
			<origin rpy = "0 0 0"  xyz = "0 0 0" />
			<mass value =  "1e-05" />
			<inertia ixx = "0.1" ixy = "0" ixz = "0" iyy = "0.1" iyz = "0" izz = "0.1" />
		</inertial>
		<collision>
			<origin rpy = "0 0 0"  xyz = "0 0 0" />
			<geometry>
				<sphere radius="1e-06" />
			</geometry>
		</collision>
	</link>
	<joint name="spine_3_rx" type="fixed">
		<parent link = "spine_3_limb" />
		<child link = "spine_3_rx" />
		<origin rpy = "0 0 0" xyz ="1.15910685e-03 2.08102167e-02 2.61528464e-03"  />
	</joint>
	<link name = "spine_3_ry">
		<inertial>
			<origin rpy = "0 0 0"  xyz = "0 0 0" />
			<mass value =  "1e-05" />
			<inertia ixx = "0.1" ixy = "0" ixz = "0" iyy = "0.1" iyz = "0" izz = "0.1" />
		</inertial>
		<collision>
			<origin rpy = "0 0 0"  xyz = "0 0 0" />
			<geometry>
				<sphere radius="1e-06" />
			</geometry>
		</collision>
	</link>
	<joint name="spine_3_ry" type="fixed">
		<parent link = "spine_3_rx" />
		<child link = "spine_3_ry" />
		<origin rpy = "0 0 0" xyz ="0 0 0"  />
	</joint>
	<link name = "spine_3_rz">
		<inertial>
			<origin rpy = "0 0 0"  xyz = "0 0 0" />
			<mass value =  "1e-05" />
			<inertia ixx = "0.1" ixy = "0" ixz = "0" iyy = "0.1" iyz = "0" izz = "0.1" />
		</inertial>
		<collision>
			<origin rpy = "0 0 0"  xyz = "0 0 0" />
			<geometry>
				<sphere radius="1e-05" />
			</geometry>
		</collision>
	</link>
	<joint name="spine_3_rz" type="fixed">
		<parent link = "spine_3_ry" />
		<child link = "spine_3_rz" />
		<origin rpy = "0 0 0" xyz ="0 0 0"  />
	</joint>
	<link name = "left_ankle_limb">
		<inertial>
			<origin rpy = "0 0 0"  xyz = "-0.0135957 -0.39796048 -0.04369333" />
			<mass value =  "2" />
			<inertia ixx = "0.1" ixy = "0" ixz = "0" iyy = "0.1" iyz = "0" izz = "0.1" />
		</inertial>
		<collision>
			<origin rpy = "0 0 0"  xyz = "-0.0135957 -0.39796048 -0.04369333" />
			<geometry>
				<mesh filename="package://Humanoid/meshes/body_parts_leftLeg.stl" />
			</geometry>
		</collision>
	</link>
	<joint name="left_knee_rzdammy" type="fixed">
		<parent link = "left_knee_rz" />
		<child link = "left_ankle_limb" />
		<origin rpy = "0 0 0" xyz ="0 0 0"  />
	</joint>
	<link name = "left_ankle_rx">
		<inertial>
			<origin rpy = "0 0 0"  xyz = "0 0 0" />
			<mass value =  "1e-05" />
			<inertia ixx = "0.1" ixy = "0" ixz = "0" iyy = "0.1" iyz = "0" izz = "0.1" />
		</inertial>
		<collision>
			<origin rpy = "0 0 0"  xyz = "0 0 0" />
			<geometry>
				<sphere radius="1e-06" />
			</geometry>
		</collision>
	</link>
	<joint name="left_ankle_rx" type="revolute">
		<parent link = "left_ankle_limb" />
		<child link = "left_ankle_rx" />
		<limit effort="1000.0" lower= "-0.4" upper= "0.7" velocity="0.5" />
		<origin rpy = "0 0 0" xyz ="8.84055197e-02 -1.08789873e+00 -2.67853457e-02"  />
		<axis xyz = "0.0 1.0 0.0" />
	</joint>
	<link name = "left_ankle_ry">
		<inertial>
			<origin rpy = "0 0 0"  xyz = "0 0 0" />
			<mass value =  "1e-05" />
			<inertia ixx = "0.1" ixy = "0" ixz = "0" iyy = "0.1" iyz = "0" izz = "0.1" />
		</inertial>
		<collision>
			<origin rpy = "0 0 0"  xyz = "0 0 0" />
			<geometry>
				<sphere radius="1e-06" />
			</geometry>
		</collision>
	</link>
	<joint name="left_ankle_ry" type="revolute">
		<parent link = "left_ankle_rx" />
		<child link = "left_ankle_ry" />
		<limit effort="1000.0" lower= "-0.5" upper= "0.5" velocity="0.5" />
		<origin rpy = "0 0 0" xyz ="0 0 0"  />
		<axis xyz = "0.0 0.0 1.0" />
	</joint>
	<link name = "left_ankle_rz">
		<inertial>
			<origin rpy = "0 0 0"  xyz = "0 0 0" />
			<mass value =  "1e-05" />
			<inertia ixx = "0.1" ixy = "0" ixz = "0" iyy = "0.1" iyz = "0" izz = "0.1" />
		</inertial>
		<collision>
			<origin rpy = "0 0 0"  xyz = "0 0 0" />
			<geometry>
				<sphere radius="1e-05" />
			</geometry>
		</collision>
	</link>
	<joint name="left_ankle_rz" type="revolute">
		<parent link = "left_ankle_ry" />
		<child link = "left_ankle_rz" />
		<limit effort="1000.0" lower= "-0.4" upper= "0.4" velocity="0.5" />
		<origin rpy = "0 0 0" xyz ="0 0 0"  />
		<axis xyz = "1.0 0.0 0.0" />
	</joint>
	<link name = "right_ankle_limb">
		<inertial>
			<origin rpy = "0 0 0"  xyz = "0.01577377 -0.3984146 -0.0423118" />
			<mass value =  "2" />
			<inertia ixx = "0.1" ixy = "0" ixz = "0" iyy = "0.1" iyz = "0" izz = "0.1" />
		</inertial>
		<collision>
			<origin rpy = "0 0 0"  xyz = "0.01577377 -0.3984146 -0.0423118" />
			<geometry>
				<mesh filename="package://Humanoid/meshes/body_parts_rightLeg.stl" />
			</geometry>
		</collision>
	</link>
	<joint name="right_knee_rzdammy" type="fixed">
		<parent link = "right_knee_rz" />
		<child link = "right_ankle_limb" />
		<origin rpy = "0 0 0" xyz ="0 0 0"  />
	</joint>
	<link name = "right_ankle_rx">
		<inertial>
			<origin rpy = "0 0 0"  xyz = "0 0 0" />
			<mass value =  "1e-05" />
			<inertia ixx = "0.1" ixy = "0" ixz = "0" iyy = "0.1" iyz = "0" izz = "0.1" />
		</inertial>
		<collision>
			<origin rpy = "0 0 0"  xyz = "0 0 0" />
			<geometry>
				<sphere radius="1e-06" />
			</geometry>
		</collision>
	</link>
	<joint name="right_ankle_rx" type="revolute">
		<parent link = "right_ankle_limb" />
		<child link = "right_ankle_rx" />
		<limit effort="1000.0" lower= "-0.4" upper= "0.7" velocity="0.5" />
		<origin rpy = "0 0 0" xyz ="-9.19818208e-02 -1.09483874e+00 -2.72625238e-02"  />
		<axis xyz = "0.0 1.0 0.0" />
	</joint>
	<link name = "right_ankle_ry">
		<inertial>
			<origin rpy = "0 0 0"  xyz = "0 0 0" />
			<mass value =  "1e-05" />
			<inertia ixx = "0.1" ixy = "0" ixz = "0" iyy = "0.1" iyz = "0" izz = "0.1" />
		</inertial>
		<collision>
			<origin rpy = "0 0 0"  xyz = "0 0 0" />
			<geometry>
				<sphere radius="1e-06" />
			</geometry>
		</collision>
	</link>
	<joint name="right_ankle_ry" type="revolute">
		<parent link = "right_ankle_rx" />
		<child link = "right_ankle_ry" />
		<limit effort="1000.0" lower= "-0.5" upper= "0.5" velocity="0.5" />
		<origin rpy = "0 0 0" xyz ="0 0 0"  />
		<axis xyz = "0.0 0.0 1.0" />
	</joint>
	<link name = "right_ankle_rz">
		<inertial>
			<origin rpy = "0 0 0"  xyz = "0 0 0" />
			<mass value =  "1e-05" />
			<inertia ixx = "0.1" ixy = "0" ixz = "0" iyy = "0.1" iyz = "0" izz = "0.1" />
		</inertial>
		<collision>
			<origin rpy = "0 0 0"  xyz = "0 0 0" />
			<geometry>
				<sphere radius="1e-05" />
			</geometry>
		</collision>
	</link>
	<joint name="right_ankle_rz" type="revolute">
		<parent link = "right_ankle_ry" />
		<child link = "right_ankle_rz" />
		<limit effort="1000.0" lower= "-0.4" upper= "0.4" velocity="0.5" />
		<origin rpy = "0 0 0" xyz ="0 0 0"  />
		<axis xyz = "1.0 0.0 0.0" />
		<origin rpy = "0 0 0" xyz ="0 0 0"  />
	</joint>
	<link name = "spine_4_limb">
		<inertial>
			<origin rpy = "0 0 0"  xyz = "0.001457 0.05292223 0.02542457" />
			<mass value =  "2" />
			<inertia ixx = "0.1" ixy = "0" ixz = "0" iyy = "0.1" iyz = "0" izz = "0.1" />
		</inertial>
		<collision>
			<origin rpy = "0 0 0"  xyz = "0.001457 0.05292223 0.02542457" />
			<geometry>
				<mesh filename="package://Humanoid/meshes/body_parts_spine2.stl" />
			</geometry>
		</collision>
	</link>
	<joint name="spine_3_rzdammy" type="fixed">
		<parent link = "spine_3_rz" />
		<child link = "spine_4_limb" />
		<origin rpy = "0 0 0" xyz ="0 0 0"  />
	</joint>
	<link name = "spine_4_rx">
		<inertial>
			<origin rpy = "0 0 0"  xyz = "0 0 0" />
			<mass value =  "1e-05" />
			<inertia ixx = "0.1" ixy = "0" ixz = "0" iyy = "0.1" iyz = "0" izz = "0.1" />
		</inertial>
		<collision>
			<origin rpy = "0 0 0"  xyz = "0 0 0" />
			<geometry>
				<sphere radius="1e-06" />
			</geometry>
		</collision>
	</link>
	<joint name="spine_4_rx" type="fixed">
		<parent link = "spine_4_limb" />
		<child link = "spine_4_rx" />
		<origin rpy = "0 0 0" xyz ="2.61610467e-03 7.37324432e-02 2.80398503e-02"  />
	</joint>
	<link name = "spine_4_ry">
		<inertial>
			<origin rpy = "0 0 0"  xyz = "0 0 0" />
			<mass value =  "1e-05" />
			<inertia ixx = "0.1" ixy = "0" ixz = "0" iyy = "0.1" iyz = "0" izz = "0.1" />
		</inertial>
		<collision>
			<origin rpy = "0 0 0"  xyz = "0 0 0" />
			<geometry>
				<sphere radius="1e-06" />
			</geometry>
		</collision>
	</link>
	<joint name="spine_4_ry" type="fixed">
		<parent link = "spine_4_rx" />
		<child link = "spine_4_ry" />
		<origin rpy = "0 0 0" xyz ="0 0 0"  />
	</joint>
	<link name = "spine_4_rz">
		<inertial>
			<origin rpy = "0 0 0"  xyz = "0 0 0" />
			<mass value =  "1e-05" />
			<inertia ixx = "0.1" ixy = "0" ixz = "0" iyy = "0.1" iyz = "0" izz = "0.1" />
		</inertial>
		<collision>
			<origin rpy = "0 0 0"  xyz = "0 0 0" />
			<geometry>
				<sphere radius="1e-05" />
			</geometry>
		</collision>
	</link>
	<joint name="spine_4_rz" type="fixed">
		<parent link = "spine_4_ry" />
		<child link = "spine_4_rz" />
		<origin rpy = "0 0 0" xyz ="0 0 0"  />
	</joint>
	<link name = "left_foot_limb">
		<inertial>
			<origin rpy = "0 0 0"  xyz = "0.02635814 -0.05579078 0.1192884" />
			<mass value =  "1" />
			<inertia ixx = "0.1" ixy = "0" ixz = "0" iyy = "0.1" iyz = "0" izz = "0.1" />
		</inertial>
		<collision>
			<origin rpy = "0 0 0"  xyz = "0.02635814 -0.05579078 0.1192884" />
			<geometry>
				<mesh filename="package://Humanoid/meshes/body_parts_leftFoot.stl" />
			</geometry>
		</collision>
	</link>
	<joint name="left_ankle_rzdammy" type="fixed">
		<parent link = "left_ankle_rz" />
		<child link = "left_foot_limb" />
		<origin rpy = "0 0 0" xyz ="0 0 0"  />
	</joint>
	<link name = "left_foot_rx">
		<inertial>
			<origin rpy = "0 0 0"  xyz = "0 0 0" />
			<mass value =  "1e-05" />
			<inertia ixx = "0.1" ixy = "0" ixz = "0" iyy = "0.1" iyz = "0" izz = "0.1" />
		</inertial>
		<collision>
			<origin rpy = "0 0 0"  xyz = "0 0 0" />
			<geometry>
				<sphere radius="1e-06" />
			</geometry>
		</collision>
	</link>
	<joint name="left_foot_rx" type="fixed">
		<parent link = "left_foot_limb" />
		<child link = "left_foot_rx" />
		<origin rpy = "0 0 0" xyz ="1.14763662e-01 -1.14368951e+00 9.25030559e-02"  />
	</joint>
	<link name = "left_foot_ry">
		<inertial>
			<origin rpy = "0 0 0"  xyz = "0 0 0" />
			<mass value =  "1e-05" />
			<inertia ixx = "0.1" ixy = "0" ixz = "0" iyy = "0.1" iyz = "0" izz = "0.1" />
		</inertial>
		<collision>
			<origin rpy = "0 0 0"  xyz = "0 0 0" />
			<geometry>
				<sphere radius="1e-06" />
			</geometry>
		</collision>
	</link>
	<joint name="left_foot_ry" type="fixed">
		<parent link = "left_foot_rx" />
		<child link = "left_foot_ry" />
		<origin rpy = "0 0 0" xyz ="0 0 0"  />
	</joint>
	<link name = "left_foot_rz">
		<inertial>
			<origin rpy = "0 0 0"  xyz = "0 0 0" />
			<mass value =  "1e-05" />
			<inertia ixx = "0.1" ixy = "0" ixz = "0" iyy = "0.1" iyz = "0" izz = "0.1" />
		</inertial>
		<collision>
			<origin rpy = "0 0 0"  xyz = "0 0 0" />
			<geometry>
				<sphere radius="1e-05" />
			</geometry>
		</collision>
	</link>
	<joint name="left_foot_rz" type="revolute">
		<parent link = "left_foot_ry" />
		<child link = "left_foot_rz" />
		<origin rpy = "0 0 0" xyz ="0 0 0"  />
		<limit effort="0.0" lower= "0" upper= "0" velocity="0.0" />
		<axis xyz = "0.0 1.0 0.0" />
	</joint>
	
	<!--<link name = "left_toe">
		<inertial>
			<origin rpy = "0 0 0"  xyz = "0 0 0" />
			<mass value =  "1e-05" />
			<inertia ixx = "0.1" ixy = "0" ixz = "0" iyy = "0.1" iyz = "0" izz = "0.1" />
		</inertial>
		<collision>
			<origin rpy = "0 0 0"  xyz = "0 0 0" />
			<geometry>
				<capsule length="0.048 " radius="0.005"  />
			</geometry>
		</collision>
	</link>
	<joint name="left_toe" type="revolute">
		<parent link = "left_foot_rz" />
		<child link = "left_toe" />
		<origin rpy = "1.5708 0 0" xyz =" 0.011 0.0  -0.01"  />
		<limit effort="0.0" lower= "0" upper= "0" velocity="0.0" />
		<axis xyz = "0.0 1.0 0.0" />
	</joint>
	<link name = "left_heel">
		<inertial>
			<origin rpy = "0 0 0"  xyz = "0 0 0" />
			<mass value =  "1e-05" />
			<inertia ixx = "0.1" ixy = "0" ixz = "0" iyy = "0.1" iyz = "0" izz = "0.1" />
		</inertial>
		<collision>
			<origin rpy = "0 0 0"  xyz = "0 0 0" />
			<geometry>
				<capsule length="0.048 " radius="0.005"/>
			</geometry>
		</collision>
	</link>
	<joint name="left_heel" type="revolute">
		<parent link = "left_toe" />
		<child link = "left_heel" />
		<origin rpy = "0 0 0" xyz ="-0.13  0.0051 -0.0"  /> 
		<limit effort="0.0" lower= "0" upper= "0" velocity="0.0" />
		<axis xyz = "0.0 1.0 0.0" />
	</joint>-->
	<link name = "right_foot_limb">
		<inertial>
			<origin rpy = "0 0 0"  xyz = "-0.02537176 -0.04814398 0.12334795" />
			<mass value =  "1" />
			<inertia ixx = "0.1" ixy = "0" ixz = "0" iyy = "0.1" iyz = "0" izz = "0.1" />
		</inertial>
		<collision>
			<origin rpy = "0 0 0"  xyz = "-0.02537176 -0.04814398 0.12334795" />
			<geometry>
				<mesh filename="package://Humanoid/meshes/body_parts_rightFoot.stl" />
			</geometry>
		</collision>
	</link>
	<joint name="right_ankle_rzdammy" type="fixed">
		<parent link = "right_ankle_rz" />
		<child link = "right_foot_limb" />
		<origin rpy = "0 0 0" xyz ="0 0 0"  />
	</joint>
	<link name = "right_foot_rx">
		<inertial>
			<origin rpy = "0 0 0"  xyz = "0 0 0" />
			<mass value =  "1e-05" />
			<inertia ixx = "0.1" ixy = "0" ixz = "0" iyy = "0.1" iyz = "0" izz = "0.1" />
		</inertial>
		<collision>
			<origin rpy = "0 0 0"  xyz = "0 0 0" />
			<geometry>
				<sphere radius="1e-06" />
			</geometry>
		</collision>
	</link>
	<joint name="right_foot_rx" type="fixed">
		<parent link = "right_foot_limb" />
		<child link = "right_foot_rx" />
		<origin rpy = "0 0 0" xyz ="-1.17353581e-01 -1.14298272e+00 9.60854292e-02"  />
	</joint>
	<link name = "right_foot_ry">
		<inertial>
			<origin rpy = "0 0 0"  xyz = "0 0 0" />
			<mass value =  "1e-05" />
			<inertia ixx = "0.1" ixy = "0" ixz = "0" iyy = "0.1" iyz = "0" izz = "0.1" />
		</inertial>
		<collision>
			<origin rpy = "0 0 0"  xyz = "0 0 0" />
			<geometry>
				<sphere radius="1e-06" />
			</geometry>
		</collision>
	</link>
	<joint name="right_foot_ry" type="fixed">
		<parent link = "right_foot_rx" />
		<child link = "right_foot_ry" />
		<origin rpy = "0 0 0" xyz ="0 0 0"  />
	</joint>
	<link name = "right_foot_rz">
		<inertial>
			<origin rpy = "0 0 0"  xyz = "0 0 0" />
			<mass value =  "1e-05" />
			<inertia ixx = "0.1" ixy = "0" ixz = "0" iyy = "0.1" iyz = "0" izz = "0.1" />
		</inertial>
		<collision>
			<origin rpy = "0 0 0"  xyz = "0 0 0" />
			<geometry>
				<sphere radius="1e-05" />
			</geometry>
		</collision>
	</link>
	<joint name="right_foot_rz" type="revolute">
		<parent link = "right_foot_ry" />
		<child link = "right_foot_rz" />
		<origin rpy = "0 0 0" xyz ="0 0 0"  />
		<limit effort="1000.0" lower= "0" upper= "0" velocity="0.5" />
		<axis xyz = "0.0 1.0 0.0" />
	</joint>
	<!--<link name = "right_toe">
		<inertial>
			<origin rpy = "0 0 0"  xyz = "0 0 0" />
			<mass value =  "1e-05" />
			<inertia ixx = "0.1" ixy = "0" ixz = "0" iyy = "0.1" iyz = "0" izz = "0.1" />
		</inertial>
		<collision>
			<origin rpy = "0 0 0"  xyz = "0 0 0" />
			<geometry>
				<capsule length="0.048 " radius="0.005"/>
			</geometry>
		</collision>
	</link>
	<joint name="right_toe" type="revolute">
		<parent link = "right_foot_rz" />
		<child link = "right_toe" />
		<origin rpy = "1.5708 0 0" xyz =" 0.011 0.0  -0.01"  />
		<limit effort="1000.0" lower= "0" upper= "0" velocity="0.5" />
		<axis xyz = "0.0 1.0 0.0" />
	</joint>

	<link name = "right_heel">
		<inertial>
			<origin rpy = "0 0 0"  xyz = "0 0 0" />
			<mass value =  "1e-05" />
			<inertia ixx = "0.1" ixy = "0" ixz = "0" iyy = "0.1" iyz = "0" izz = "0.1" />
		</inertial>
		<collision>
			<origin rpy = "0 0 0"  xyz = "0 0 0" />
			<geometry>
				<capsule length="0.048 " radius="0.005" />
			</geometry>
		</collision>
	</link>
	<joint name="right_heel" type="revolute">
		<parent link = "right_toe" />
		<child link = "right_heel" />
		<origin rpy = "0 0 0" xyz ="-0.13  -0.0051 0.0"  />
		<limit effort="0.0" lower= "0" upper= "0" velocity="0.0" />
		<axis xyz = "0.0 1.0 0.0" />
	</joint>-->
	<link name = "neck_limb">
		<inertial>
			<origin rpy = "0 0 0"  xyz = "-0.00277839 0.21387038 -0.04285703" />
			<mass value =  "1" />
			<inertia ixx = "0.1" ixy = "0" ixz = "0" iyy = "0.1" iyz = "0" izz = "0.1" />
		</inertial>
		<collision>
			<origin rpy = "0 0 0"  xyz = "-0.00277839 0.21387038 -0.04285703" />
			<geometry>
				<mesh filename="package://Humanoid/meshes/body_parts_neck.stl" />
			</geometry>
		</collision>
	</link>
	<joint name="spine_4_rzdammy" type="fixed">
		<parent link = "spine_4_rz" />
		<child link = "neck_limb" />
		<origin rpy = "0 0 0" xyz ="0 0 0"  />
	</joint>
	<link name = "neck_rx">
		<inertial>
			<origin rpy = "0 0 0"  xyz = "0.0160  0.0022 -0.048" />
			<mass value =  "1e-05" />
			<inertia ixx = "0.1" ixy = "0" ixz = "0" iyy = "0.1" iyz = "0" izz = "0.1" />
		</inertial>
		<collision>
			<origin rpy = "0 0 0"  xyz = "0.0080  0.001145 -0.0247" />
			<geometry>
				<sphere radius="0.00001" />
			</geometry>
		</collision>
	</link>
	<joint name="neck_rx" type="revolute">
		<parent link = "neck_limb" />
		<child link = "neck_rx" />
		<limit effort="1000.0" lower= "-0.6" upper= "0.6" velocity="0.5" />
		<origin rpy = "0 0 0" xyz ="-1.17353581e-01 -1.14298272e+00 9.60854292e-02"  />
		<axis xyz = "0.0 1.0 0.0" />
	</joint>
	<link name = "neck_ry">
		<inertial>
			<origin rpy = "0 0 0"  xyz = "0 0 0" />
			<mass value =  "1e-05" />
			<inertia ixx = "0.1" ixy = "0" ixz = "0" iyy = "0.1" iyz = "0" izz = "0.1" />
		</inertial>
		<collision>
			<origin rpy = "0 0 0"  xyz = "0 0 0" />
			<geometry>
				<sphere radius="1e-06" />
			</geometry>
		</collision>
	</link>
	<joint name="neck_ry" type="revolute">
		<parent link = "neck_rx" />
		<child link = "neck_ry" />
		<limit effort="1000.0" lower= "-0.6" upper= "0.6" velocity="0.5" />
		<origin rpy = "0 0 0" xyz ="0 0 0"  />
		<axis xyz = "0.0 0.0 1.0" />
	</joint>
	<link name = "neck_rz">
		<inertial>
			<origin rpy = "0 0 0"  xyz = "0 0 0 " />
			<mass value =  "1e-05" />
			<inertia ixx = "0.1" ixy = "0" ixz = "0" iyy = "0.1" iyz = "0" izz = "0.1" />
		</inertial>
		<collision>
			<origin rpy = "0 0 0"  xyz = "0 0 0 " />
			<geometry>
				<sphere radius="0.0000001" />
			</geometry>
		</collision>
	</link>
	<joint name="neck_rz" type="revolute">
		<parent link = "neck_ry" />
		<child link = "neck_rz" />
		<limit effort="1000.0" lower= "-0.3" upper= "0.3" velocity="0.5" />
		<origin rpy = "0 0 0" xyz ="0 0 0"  />
		<axis xyz = "1.0 0.0 0.0" />
	</joint>
	<link name = "left_clavicle_rx">
		<inertial>
			<origin rpy = "0 0 0"  xyz = "0.07884474 0.12174932 -0.03408961" />
			<mass value =  "1e-05" />
			<inertia ixx = "0.1" ixy = "0" ixz = "0" iyy = "0.1" iyz = "0" izz = "0.1" />
		</inertial>
		<collision>
			<origin rpy = "0 0 0"  xyz = "0.07884474 0.12174932 -0.03408961" />
			<geometry>
				<sphere radius="1e-06" />
			</geometry>
		</collision>
	</link>
	<joint name="left_clavicle_rx" type="fixed">
		<parent link = "spine_4_rz" />
		<child link = "left_clavicle_rx" />
		<origin rpy = "0 0 0" xyz ="8.14608485e-02 1.95481762e-01 -6.04975596e-03"  />
	</joint>
	<link name = "left_clavicle_ry">
		<inertial>
			<origin rpy = "0 0 0"  xyz = "0 0 0" />
			<mass value =  "1e-05" />
			<inertia ixx = "0.1" ixy = "0" ixz = "0" iyy = "0.1" iyz = "0" izz = "0.1" />
		</inertial>
		<collision>
			<origin rpy = "0 0 0"  xyz = "0 0 0" />
			<geometry>
				<sphere radius="1e-06" />
			</geometry>
		</collision>
	</link>
	<joint name="left_clavicle_ry" type="revolute">
		<parent link = "left_clavicle_rx" />
		<child link = "left_clavicle_ry" />
		<limit effort="1000.0" lower= "-0.6" upper= "0.4" velocity="0.5" />
		<origin rpy = "0 0 0" xyz ="0 0 0"  />
		<axis xyz = "0.0 0.0 1.0" />
	</joint>
	<link name = "left_clavicle_rz">
		<inertial>
			<origin rpy = "0 0 0"  xyz = "0 0 0" />
			<mass value =  "1e-05" />
			<inertia ixx = "0.1" ixy = "0" ixz = "0" iyy = "0.1" iyz = "0" izz = "0.1" />
		</inertial>
		<collision>
			<origin rpy = "0 0 0"  xyz = "0 0 0" />
			<geometry>
				<sphere radius="1e-05" />
			</geometry>
		</collision>
	</link>
	<joint name="left_clavicle_rz" type="revolute">
		<parent link = "left_clavicle_ry" />
		<child link = "left_clavicle_rz" />
		<limit effort="1000.0" lower= "-0.4" upper= "0.4" velocity="0.5" />
		<origin rpy = "0 0 0" xyz ="0 0 0"  />
		<axis xyz = "1.0 0.0 0.0" />
	</joint>
	<link name = "right_clavicle_rx">
		<inertial>
			<origin rpy = "0 0 0"  xyz = "-0.08175919 0.11883285 -0.03861528" />
			<mass value =  "1e-05" />
			<inertia ixx = "0.1" ixy = "0" ixz = "0" iyy = "0.1" iyz = "0" izz = "0.1" />
		</inertial>
		<collision>
			<origin rpy = "0 0 0"  xyz = "-0.08175919 0.11883285 -0.03861528" />
			<geometry>
				<sphere radius="1e-06" />
			</geometry>
		</collision>
	</link>
	<joint name="right_clavicle_rx" type="fixed">
		<parent link = "spine_4_rz" />
		<child link = "right_clavicle_rx" />
		<origin rpy = "0 0 0" xyz ="-7.91430846e-02 1.92565292e-01 -1.05754286e-02"  />
	</joint>
	<link name = "right_clavicle_ry">
		<inertial>
			<origin rpy = "0 0 0"  xyz = "0 0 0" />
			<mass value =  "1e-05" />
			<inertia ixx = "0.1" ixy = "0" ixz = "0" iyy = "0.1" iyz = "0" izz = "0.1" />
		</inertial>
		<collision>
			<origin rpy = "0 0 0"  xyz = "0 0 0" />
			<geometry>
				<sphere radius="1e-06" />
			</geometry>
		</collision>
	</link>
	<joint name="right_clavicle_ry" type="revolute">
		<parent link = "right_clavicle_rx" />
		<child link = "right_clavicle_ry" />
		<limit effort="1000.0" lower= "-0.4" upper= "0.6" velocity="0.5" />
		<origin rpy = "0 0 0" xyz ="0 0 0"  />
		<axis xyz = "0.0 0.0 1.0" />
	</joint>
	<link name = "right_clavicle_rz">
		<inertial>
			<origin rpy = "0 0 0"  xyz = "0 0 0" />
			<mass value =  "1e-05" />
			<inertia ixx = "0.1" ixy = "0" ixz = "0" iyy = "0.1" iyz = "0" izz = "0.1" />
		</inertial>
		<collision>
			<origin rpy = "0 0 0"  xyz = "0 0 0" />
			<geometry>
				<sphere radius="1e-05" />
			</geometry>
		</collision>
	</link>
	<joint name="right_clavicle_rz" type="revolute">
		<parent link = "right_clavicle_ry" />
		<child link = "right_clavicle_rz" />
		<limit effort="1000.0" lower= "-0.4" upper= "0.4" velocity="0.5" />
		<origin rpy = "0 0 0" xyz ="0 0 0"  />
		<axis xyz = "1.0 0.0 0.0" />
	</joint>
	<link name = "head_limb">
		<inertial>
			<origin rpy = "0 0 0"  xyz = "0.00515184 0.06496963 0.05134897" />
			<mass value =  "1" />
			<inertia ixx = "0.1" ixy = "0" ixz = "0" iyy = "0.1" iyz = "0" izz = "0.1" />
		</inertial>
		<collision>
			<origin rpy = "0 0 0"  xyz = "0.00515184 0.06496963 0.05134897" />
			<geometry>
				<mesh filename="package://Humanoid/meshes/body_parts_head.stl" />
			</geometry>
		</collision>
	</link>
	<joint name="neck_rzdammy" type="fixed">
		<parent link = "neck_rz" />
		<child link = "head_limb" />
		<origin rpy = "0 0 0" xyz ="0 0 0"  />
	</joint>
	<link name = "head_rx">
		<inertial>
			<origin rpy = "0 0 0"  xyz = "0 0 0" />
			<mass value =  "1e-05" />
			<inertia ixx = "0.1" ixy = "0" ixz = "0" iyy = "0.1" iyz = "0" izz = "0.1" />
		</inertial>
		<collision>
			<origin rpy = "0 0 0"  xyz = "0 0 0" />
			<geometry>
				<sphere radius="1e-06" />
			</geometry>
		</collision>
	</link>
	<joint name="head_rx" type="fixed">
		<parent link = "head_limb" />
		<child link = "head_rx" />
		<origin rpy = "0 0 0" xyz ="4.98955511e-03 3.52572441e-01 3.65317874e-02"  />
	</joint>
	<link name = "head_ry">
		<inertial>
			<origin rpy = "0 0 0"  xyz = "0.016081 0.0000 0.005642" />
			<mass value =  "1e-05" />
			<inertia ixx = "0.1" ixy = "0" ixz = "0" iyy = "0.1" iyz = "0" izz = "0.1" />
		</inertial>
		<collision>
			<origin rpy = "0 0 0"  xyz = "0.016081 0.0000 0.005642" />
			<geometry>
				<sphere radius="0.000001" />
			</geometry>
		</collision>
	</link>
	<joint name="head_ry" type="fixed">
		<parent link = "head_rx" />
		<child link = "head_ry" />
		<origin rpy = "0 0 0" xyz ="0 0 0"  />
	</joint>
	<link name = "head_rz">
		<inertial>
			<origin rpy = "0 0 0"  xyz = "0 0 0" />
			<mass value =  "1e-05" />
			<inertia ixx = "0.1" ixy = "0" ixz = "0" iyy = "0.1" iyz = "0" izz = "0.1" />
		</inertial>
		<collision>
			<origin rpy = "0 0 0"  xyz = "0 0 0" />
			<geometry>
				<sphere radius="1e-05" />
			</geometry>
		</collision>
	</link>
	<joint name="head_rz" type="fixed">
		<parent link = "head_ry" />
		<child link = "head_rz" />
		<origin rpy = "0 0 0" xyz ="0 0 0"  />
	</joint>
	<link name = "left_shoulder_limb">
		<inertial>
			<origin rpy = "0 0 0"  xyz = "0.09097692 0.03046888 -0.00886815" />
			<mass value =  "1" />
			<inertia ixx = "0.1" ixy = "0" ixz = "0" iyy = "0.1" iyz = "0" izz = "0.1" />
		</inertial>
		<collision>
			<origin rpy = "0 0 0"  xyz = "0.09097692 0.03046888 -0.00886815" />
			<geometry>
				<mesh filename="package://Humanoid/meshes/body_parts_leftShoulder.stl" />
			</geometry>
		</collision>
	</link>
	<joint name="left_clavicle_rzdammy" type="fixed">
		<parent link = "left_clavicle_rz" />
		<child link = "left_shoulder_limb" />
		<origin rpy = "0 0 0" xyz ="0 0 0"  />
	</joint>
	<link name = "left_shoulder_rx">
		<inertial>
			<origin rpy = "0 0 0"  xyz = "0 0 0" />
			<mass value =  "1e-05" />
			<inertia ixx = "0.1" ixy = "0" ixz = "0" iyy = "0.1" iyz = "0" izz = "0.1" />
		</inertial>
		<collision>
			<origin rpy = "0 0 0"  xyz = "0 0 0" />
			<geometry>
				<sphere radius="1e-06" />
			</geometry>
		</collision>
	</link>
	<joint name="left_shoulder_rx" type="fixed">
		<parent link = "left_shoulder_limb" />
		<child link = "left_shoulder_rx" />
		<origin rpy = "0 0 0" xyz ="1.72437772e-01 2.25950643e-01 -1.49179073e-02"  />
	</joint>
	<link name = "left_shoulder_ry">
		<inertial>
			<origin rpy = "0 0 0"  xyz = "-0.0034 -0.035 0.01825" />
			<mass value =  "1e-05" />
			<inertia ixx = "0.1" ixy = "0" ixz = "0" iyy = "0.1" iyz = "0" izz = "0.1" />
		</inertial>
		<collision>
			<origin rpy = "0 0 0"  xyz = "-0.0034 -0.035 0.01825" />
			<geometry>
				<sphere radius="0.0000001" />
			</geometry>
		</collision>
	</link>
	<joint name="left_shoulder_ry" type="revolute">
		<parent link = "left_shoulder_rx" />
		<child link = "left_shoulder_ry" />
		<limit effort="1000.0" lower= "-2.0" upper= "0.6" velocity="0.5" />
		<origin rpy = "0 0 0" xyz ="0 0 0"  />
		<axis xyz = "0.0 0.0 1.0" />
	</joint>
	<link name = "left_shoulder_rz">
		<inertial>
			<origin rpy = "0 0 0"  xyz = "0 0 0" />
			<mass value =  "1e-05" />
			<inertia ixx = "0.1" ixy = "0" ixz = "0" iyy = "0.1" iyz = "0" izz = "0.1" />
		</inertial>
		<collision>
			<origin rpy = "0 0 0"  xyz = "0 0 0" />
			<geometry>
				<sphere radius="1e-05" />
			</geometry>
		</collision>
	</link>
	<joint name="left_shoulder_rz" type="revolute">
		<parent link = "left_shoulder_ry" />
		<child link = "left_shoulder_rz" />
		<limit effort="1000.0" lower= "-1.0" upper= "1.0" velocity="0.5" />
		<origin rpy = "0 0 0" xyz ="0 0 0"  />
		<axis xyz = "1.0 0.0 0.0" />
	</joint>
	<link name = "right_shoulder_limb">
		<inertial>
			<origin rpy = "0 0 0"  xyz = "-0.09601238 0.03255117 -0.00914307" />
			<mass value =  "1" />
			<inertia ixx = "0.1" ixy = "0" ixz = "0" iyy = "0.1" iyz = "0" izz = "0.1" />
		</inertial>
		<collision>
			<origin rpy = "0 0 0"  xyz = "-0.09601238 0.03255117 -0.00914307" />
			<geometry>
				<mesh filename="package://Humanoid/meshes/body_parts_rightShoulder.stl" />
			</geometry>
		</collision>
	</link>
	<joint name="right_clavicle_rzdammy" type="fixed">
		<parent link = "right_clavicle_rz" />
		<child link = "right_shoulder_limb" />
		<origin rpy = "0 0 0" xyz ="0 0 0"  />
	</joint>
	<link name = "right_shoulder_rx">
		<inertial>
			<origin rpy = "0 0 0"  xyz = "0 0 0" />
			<mass value =  "1e-05" />
			<inertia ixx = "0.1" ixy = "0" ixz = "0" iyy = "0.1" iyz = "0" izz = "0.1" />
		</inertial>
		<collision>
			<origin rpy = "0 0 0"  xyz = "0 0 0" />
			<geometry>
				<sphere radius="1e-06" />
			</geometry>
		</collision>
	</link>
	<joint name="right_shoulder_rx" type="fixed">
		<parent link = "right_shoulder_limb" />
		<child link = "right_shoulder_rx" />
		<origin rpy = "0 0 0" xyz ="1.72437772e-01 2.25950643e-01 -1.49179073e-02"  />
	</joint>
	<link name = "right_shoulder_ry">
		<inertial>
			<origin rpy = "0 0 0"  xyz = "-0.0034 0.035 0.01825" />
			<mass value =  "1e-05" />
			<inertia ixx = "0.1" ixy = "0" ixz = "0" iyy = "0.1" iyz = "0" izz = "0.1" />
		</inertial>
		<collision>
			<origin rpy = "0 0 0"  xyz = "-0.0034 0.035 0.01825" />
			<geometry>
				<sphere radius="0.000001" />
			</geometry>
		</collision>
	</link>
	<joint name="right_shoulder_ry" type="revolute">
		<parent link = "right_shoulder_rx" />
		<child link = "right_shoulder_ry" />
		<limit effort="1000.0" lower= "-0.6" upper= "2.0" velocity="0.5" />
		<origin rpy = "0 0 0" xyz ="0 0 0"  />
		<axis xyz = "0.0 0.0 1.0" />
	</joint>
	<link name = "right_shoulder_rz">
		<inertial>
			<origin rpy = "0 0 0"  xyz = "0 0 0" />
			<mass value =  "1e-05" />
			<inertia ixx = "0.1" ixy = "0" ixz = "0" iyy = "0.1" iyz = "0" izz = "0.1" />
		</inertial>
		<collision>
			<origin rpy = "0 0 0"  xyz = "0 0 0" />
			<geometry>
				<sphere radius="1e-05" />
			</geometry>
		</collision>
	</link>
	<joint name="right_shoulder_rz" type="revolute">
		<parent link = "right_shoulder_ry" />
		<child link = "right_shoulder_rz" />
		<limit effort="1000.0" lower= "-1.0" upper= "1.0" velocity="0.5" />
		<origin rpy = "0 0 0" xyz ="0 0 0"  />
		<axis xyz = "1.0 0.0 0.0" />
	</joint>
	<link name = "left_elbow_limb">
		<inertial>
			<origin rpy = "0 0 0"  xyz = "0.2596122 -0.01277207 -0.02745643" />
			<mass value =  "1" />
			<inertia ixx = "0.1" ixy = "0" ixz = "0" iyy = "0.1" iyz = "0" izz = "0.1" />
		</inertial>
		<collision>
			<origin rpy = "1.59 0 0"  xyz = "0.2596122 -0.01277207 -0.02745643" />
			<geometry>
				<mesh filename="package://Humanoid/meshes/body_parts_leftArm.stl" />
			</geometry>
		</collision>
	</link>
	<joint name="left_shoulder_rzdammy" type="fixed">
		<parent link = "left_shoulder_rz" />
		<child link = "left_elbow_limb" />
		<origin rpy = "0 0 0" xyz ="0 0 0"  />
	</joint>
	<link name = "left_elbow_rx">
		<inertial>
			<origin rpy = "0 0 0"  xyz = "0 0 0" />
			<mass value =  "1e-05" />
			<inertia ixx = "0.1" ixy = "0" ixz = "0" iyy = "0.1" iyz = "0" izz = "0.1" />
		</inertial>
		<collision>
			<origin rpy = "0 0 0"  xyz = "0.00 -0.02 0.00" />
			<geometry>
				<sphere radius="0.03" />
			</geometry>
		</collision>
	</link>
	<joint name="left_elbow_rx" type="revolute">
		<parent link = "left_elbow_limb" />
		<child link = "left_elbow_rx" />
		<limit effort="1000.0" lower= "-1.4" upper= "0.9" velocity="0.5" />
		<origin rpy = "0 0 0" xyz ="4.32049990e-01 2.13178575e-01 -4.23743390e-02"  />
		<axis xyz = "0.0 1.0 0.0" />
	</joint>
	<link name = "left_elbow_ry">
		<inertial>
			<origin rpy = "0 0 0"  xyz = "0 0 0" />
			<mass value =  "1e-05" />
			<inertia ixx = "0.1" ixy = "0" ixz = "0" iyy = "0.1" iyz = "0" izz = "0.1" />
		</inertial>
		<collision>
			<origin rpy = "0 0 0"  xyz = "0 0 0" />
			<geometry>
				<sphere radius="1e-06" />
			</geometry>
		</collision>
	</link>
	<joint name="left_elbow_ry" type="revolute">
		<parent link = "left_elbow_rx" />
		<child link = "left_elbow_ry" />
		<limit effort="1000.0" lower= "-2.7" upper= "0.0" velocity="0.5" />
		<origin rpy = "0 0 0" xyz ="0 0 0"  />
		<axis xyz = "0.0 0.0 1.0" />
	</joint>
	<link name = "left_elbow_rz">
		<inertial>
			<origin rpy = "0 0 0"  xyz = "0 0 0" />
			<mass value =  "1e-05" />
			<inertia ixx = "0.1" ixy = "0" ixz = "0" iyy = "0.1" iyz = "0" izz = "0.1" />
		</inertial>
		<collision>
			<origin rpy = "0 0 0"  xyz = "0 0 0" />
			<geometry>
				<sphere radius="1e-05" />
			</geometry>
		</collision>
	</link>
	<joint name="left_elbow_rz" type="fixed">
		<parent link = "left_elbow_ry" />
		<child link = "left_elbow_rz" />
		<origin rpy = "0 0 0" xyz ="0 0 0"  />
	</joint>
	<link name = "right_elbow_limb">
		<inertial>
			<origin rpy = "0 0 0"  xyz = "-0.25374195 -0.01332924 -0.02140098" />
			<mass value =  "1" />
			<inertia ixx = "0.1" ixy = "0" ixz = "0" iyy = "0.1" iyz = "0" izz = "0.1" />
		</inertial>

		<collision>
			<origin rpy = "1.59 0 0"  xyz = "-0.25374195 -0.01332924 -0.02140098" />
			<geometry>
				<mesh filename="package://Humanoid/meshes/body_parts_rightArm.stl" />
			</geometry>
		</collision>
	</link>
	<joint name="right_shoulder_rzdammy" type="fixed">
		<parent link = "right_shoulder_rz" />
		<child link = "right_elbow_limb" />
		<origin rpy = "0 0 0" xyz ="0 0 0"  />
	</joint>
	<link name = "right_elbow_rx">
		<inertial>
			<origin rpy = "0 0 0"  xyz = "0 0 0" />
			<mass value =  "1e-05" />
			<inertia ixx = "0.1" ixy = "0" ixz = "0" iyy = "0.1" iyz = "0" izz = "0.1" />
		</inertial>
		<collision>
			<origin rpy = "0 0 0"  xyz = "0.00 0.02 0.00" />
			<geometry>
				<sphere radius="0.03" />
			</geometry>
		</collision>
	</link>
	<joint name="right_elbow_rx" type="revolute">
		<parent link = "right_elbow_limb" />
		<child link = "right_elbow_rx" />
		<limit effort="1000.0" lower= "-1.4" upper= "0.9" velocity="0.5" />
		<origin rpy = "0 0 0" xyz ="4.32049990e-01 2.13178575e-01 -4.23743390e-02"  />
		<axis xyz = "0.0 1.0 0.0" />
	</joint>
	<link name = "right_elbow_ry">
		<inertial>
			<origin rpy = "0 0 0"  xyz = "0 0 0" />
			<mass value =  "1e-05" />
			<inertia ixx = "0.1" ixy = "0" ixz = "0" iyy = "0.1" iyz = "0" izz = "0.1" />
		</inertial>
		<collision>
			<origin rpy = "0 0 0"  xyz = "0 0 0" />
			<geometry>
				<sphere radius="1e-06" />
			</geometry>
		</collision>
	</link>
	<joint name="right_elbow_ry" type="revolute">
		<parent link = "right_elbow_rx" />
		<child link = "right_elbow_ry" />
		<limit effort="1000.0" lower= "0.0" upper= "2.7" velocity="0.5" />
		<origin rpy = "0 0 0" xyz ="0 0 0"  />
		<axis xyz = "0.0 0.0 1.0" />
	</joint>
	<link name = "right_elbow_rz">
		<inertial>
			<origin rpy = "0 0 0"  xyz = "0 0 0" />
			<mass value =  "1e-05" />
			<inertia ixx = "0.1" ixy = "0" ixz = "0" iyy = "0.1" iyz = "0" izz = "0.1" />
		</inertial>
		<collision>
			<origin rpy = "0 0 0"  xyz = "0 0 0" />
			<geometry>
				<sphere radius="1e-05" />
			</geometry>
		</collision>
	</link>
	<joint name="right_elbow_rz" type="fixed">
		<parent link = "right_elbow_ry" />
		<child link = "right_elbow_rz" />
		<origin rpy = "0 0 0" xyz ="0 0 0"  />
	</joint>
	<link name = "left_lowarm_limb">
		<inertial>
			<origin rpy = "0 0 0"  xyz = "0.2492336 0.00898604 -0.00117092" />
			<mass value =  "1" />
			<inertia ixx = "0.1" ixy = "0" ixz = "0" iyy = "0.1" iyz = "0" izz = "0.1" />
		</inertial>
		<collision>
			<origin rpy = "1.59 0 0"  xyz = "0.2492336 0.00898604 -0.00117092" />
			<geometry>
				<mesh filename="package://Humanoid/meshes/body_parts_leftForeArm.stl" />
			</geometry>
		</collision>
	</link>
	<joint name="left_elbow_rzdammy" type="fixed">
		<parent link = "left_elbow_rz" />
		<child link = "left_lowarm_limb" />
		<origin rpy = "0 0 0" xyz ="0 0 0"  />
	</joint>
	<link name = "left_lowarm_rx">
		<inertial>
			<origin rpy = "0 0 0"  xyz = "0 0 0" />
			<mass value =  "1e-05" />
			<inertia ixx = "0.1" ixy = "0" ixz = "0" iyy = "0.1" iyz = "0" izz = "0.1" />
		</inertial>
		<collision>
			<origin rpy = "0 0 0"  xyz = "0 0 0" />
			<geometry>
				<sphere radius="1e-06" />
			</geometry>
		</collision>
	</link>
	<joint name="left_lowarm_rx" type="fixed">
		<parent link = "left_lowarm_limb" />
		<child link = "left_lowarm_rx" />
		<origin rpy = "0 0 0" xyz ="4.32049990e-01 2.13178575e-01 -4.23743390e-02"  />
	</joint>
	<link name = "left_lowarm_ry">
		<inertial>
			<origin rpy = "0 0 0"  xyz = "0 0 0" />
			<mass value =  "1e-05" />
			<inertia ixx = "0.1" ixy = "0" ixz = "0" iyy = "0.1" iyz = "0" izz = "0.1" />
		</inertial>
		<collision>
			<origin rpy = "0 0 0"  xyz = "0 0 0" />
			<geometry>
				<sphere radius="1e-06" />
			</geometry>
		</collision>
	</link>
	<joint name="left_lowarm_ry" type="fixed">
		<parent link = "left_lowarm_rx" />
		<child link = "left_lowarm_ry" />
		<origin rpy = "0 0 0" xyz ="0 0 0"  />
	</joint>
	<link name = "left_lowarm_rz">
		<inertial>
			<origin rpy = "0 0 0"  xyz = "0 0 0" />
			<mass value =  "1e-05" />
			<inertia ixx = "0.1" ixy = "0" ixz = "0" iyy = "0.1" iyz = "0" izz = "0.1" />
		</inertial>
		<collision>
			<origin rpy = "0 0 0"  xyz = "0 0 0" />
			<geometry>
				<sphere radius="1e-05" />
			</geometry>
		</collision>
	</link>
	<joint name="left_lowarm_rz" type="fixed">
		<parent link = "left_lowarm_ry" />
		<child link = "left_lowarm_rz" />
		<origin rpy = "0 0 0" xyz ="0 0 0"  />
	</joint>
	<link name = "right_lowarm_limb">
		<inertial>
			<origin rpy = "0 0 0"  xyz = "-0.2552981 0.0077723 -0.0055592" />
			<mass value =  "1" />
			<inertia ixx = "0.1" ixy = "0" ixz = "0" iyy = "0.1" iyz = "0" izz = "0.1" />
		</inertial>
		<collision>
			<origin rpy = "1.59 0 0"  xyz = "-0.2552981 0.0077723 -0.0055592" />
			<geometry>
				<mesh filename="package://Humanoid/meshes/body_parts_rightForeArm.stl" />
			</geometry>
		</collision>
	</link>
	<joint name="right_elbow_rzdammy" type="fixed">
		<parent link = "right_elbow_rz" />
		<child link = "right_lowarm_limb" />
		<origin rpy = "0 0 0" xyz ="0 0 0"  />
	</joint>
	<link name = "right_lowarm_rx">
		<inertial>
			<origin rpy = "0 0 0"  xyz = "0 0 0" />
			<mass value =  "1e-05" />
			<inertia ixx = "0.1" ixy = "0" ixz = "0" iyy = "0.1" iyz = "0" izz = "0.1" />
		</inertial>
		<collision>
			<origin rpy = "0 0 0"  xyz = "0 0 0" />
			<geometry>
				<sphere radius="1e-06" />
			</geometry>
		</collision>
	</link>
	<joint name="right_lowarm_rx" type="fixed">
		<parent link = "right_lowarm_limb" />
		<child link = "right_lowarm_rx" />
		<origin rpy = "0 0 0" xyz ="4.32049990e-01 2.13178575e-01 -4.23743390e-02"  />
	</joint>
	<link name = "right_lowarm_ry">
		<inertial>
			<origin rpy = "0 0 0"  xyz = "0 0 0" />
			<mass value =  "1e-05" />
			<inertia ixx = "0.1" ixy = "0" ixz = "0" iyy = "0.1" iyz = "0" izz = "0.1" />
		</inertial>
		<collision>
			<origin rpy = "0 0 0"  xyz = "0 0 0" />
			<geometry>
				<sphere radius="1e-06" />
			</geometry>
		</collision>
	</link>
	<joint name="right_lowarm_ry" type="fixed">
		<parent link = "right_lowarm_rx" />
		<child link = "right_lowarm_ry" />
		<origin rpy = "0 0 0" xyz ="0 0 0"  />
	</joint>
	<link name = "right_lowarm_rz">
		<inertial>
			<origin rpy = "0 0 0"  xyz = "0 0 0" />
			<mass value =  "1e-05" />
			<inertia ixx = "0.1" ixy = "0" ixz = "0" iyy = "0.1" iyz = "0" izz = "0.1" />
		</inertial>
		<collision>
			<origin rpy = "0 0 0"  xyz = "0 0 0" />
			<geometry>
				<sphere radius="1e-05" />
			</geometry>
		</collision>
	</link>
	<joint name="right_lowarm_rz" type="fixed">
		<parent link = "right_lowarm_ry" />
		<child link = "right_lowarm_rz" />
		<origin rpy = "0 0 0" xyz ="0 0 0"  />
	</joint>
	<link name = "left_hand_limb">
		<inertial>
			<origin rpy = "0 0 0"  xyz = "0.08404213 -0.00816153 0.01494537" />
			<mass value =  "0.5" />
			<inertia ixx = "0.1" ixy = "0" ixz = "0" iyy = "0.1" iyz = "0" izz = "0.1" />
		</inertial>
		<collision>
			<origin rpy = "0 0 0"  xyz = "0.08404213 -0.00816153 0.01494537" />
			<geometry>
				<mesh filename="package://Humanoid/meshes/body_parts_leftHand.stl" />
			</geometry>
		</collision>
	</link>
	<joint name="left_lowarm_rzdammy" type="revolute">
		<parent link = "left_lowarm_rz" />
		<child link = "left_hand_limb" />
		<origin rpy = "0 0 0" xyz ="0 0 0"  />
		<limit effort="1000.0" lower= "0" upper= "0" velocity="0.5" />
		<axis xyz = "0.0 1.0 0.0" />
	</joint>
	<link name = "left_hand_rx">
		<inertial>
			<origin rpy = "0 0 0"  xyz = "0 0 0" />
			<mass value =  "1e-05" />
			<inertia ixx = "0.1" ixy = "0" ixz = "0" iyy = "0.1" iyz = "0" izz = "0.1" />
		</inertial>
		<collision>
			<origin rpy = "0 0 0"  xyz = "0 0 0" />
			<geometry>
				<sphere radius="1e-06" />
			</geometry>
		</collision>
	</link>
	<joint name="left_hand_rx" type="fixed">
		<parent link = "left_hand_limb" />
		<child link = "left_hand_rx" />
		<origin rpy = "0 0 0" xyz ="7.65325725e-01 2.14003086e-01 -5.84906228e-02"  />
	</joint>
	<link name = "left_hand_ry">
		<inertial>
			<origin rpy = "0 0 0"  xyz = "0 0 0" />
			<mass value =  "1e-05" />
			<inertia ixx = "0.1" ixy = "0" ixz = "0" iyy = "0.1" iyz = "0" izz = "0.1" />
		</inertial>
		<collision>
			<origin rpy = "0 0 0"  xyz = "0 0 0" />
			<geometry>
				<sphere radius="1e-06" />
			</geometry>
		</collision>
	</link>
	<joint name="left_hand_ry" type="fixed">
		<parent link = "left_hand_rx" />
		<child link = "left_hand_ry" />
		<origin rpy = "0 0 0" xyz ="0 0 0"  />
	</joint>
	<link name = "left_hand_rz">
		<inertial>
			<origin rpy = "0 0 0"  xyz = "0 0 0" />
			<mass value =  "1e-05" />
			<inertia ixx = "0.1" ixy = "0" ixz = "0" iyy = "0.1" iyz = "0" izz = "0.1" />
		</inertial>
		<collision>
			<origin rpy = "0 0 0"  xyz = "0 0 0" />
			<geometry>
				<sphere radius="1e-05" />
			</geometry>
		</collision>
	</link>
	<joint name="left_hand_rz" type="fixed">
		<parent link = "left_hand_ry" />
		<child link = "left_hand_rz" />
		<origin rpy = "0 0 0" xyz ="0 0 0"  />
	</joint>
	<link name = "right_hand_limb">
		<inertial>
			<origin rpy = "0 0 0"  xyz = "-0.08462191 -0.00611724 -0.01031508" />
			<mass value =  "0.5" />
			<inertia ixx = "0.1" ixy = "0" ixz = "0" iyy = "0.1" iyz = "0" izz = "0.1" />
		</inertial>
		<collision>
			<origin rpy = "0 0 0"  xyz = "-0.08462191 -0.00611724 -0.01031508" />
			<geometry>
				<mesh filename="package://Humanoid/meshes/body_parts_rightHand.stl" />
			</geometry>
		</collision>
	</link>
	<joint name="right_lowarm_rzdammy" type="revolute">
		<parent link = "right_lowarm_rz" />
		<child link = "right_hand_limb" />
		<origin rpy = "0 0 0" xyz ="0 0 0"  />
		<limit effort="1000.0" lower= "0" upper= "0" velocity="0.5" />
		<axis xyz = "0.0 1.0 0.0" />
	</joint>
	<link name = "right_hand_rx">
		<inertial>
			<origin rpy = "0 0 0"  xyz = "0 0 0" />
			<mass value =  "1e-05" />
			<inertia ixx = "0.1" ixy = "0" ixz = "0" iyy = "0.1" iyz = "0" izz = "0.1" />
		</inertial>
		<collision>
			<origin rpy = "0 0 0"  xyz = "0 0 0" />
			<geometry>
				<sphere radius="1e-06" />
			</geometry>
		</collision>
	</link>
	<joint name="right_hand_rx" type="fixed">
		<parent link = "right_hand_limb" />
		<child link = "right_hand_rx" />
		<origin rpy = "0 0 0" xyz ="-7.68817425e-01 2.13442281e-01 -5.69937602e-02"  />
	</joint>
	<link name = "right_hand_ry">
		<inertial>
			<origin rpy = "0 0 0"  xyz = "0 0 0" />
			<mass value =  "1e-05" />
			<inertia ixx = "0.1" ixy = "0" ixz = "0" iyy = "0.1" iyz = "0" izz = "0.1" />
		</inertial>
		<collision>
			<origin rpy = "0 0 0"  xyz = "0 0 0" />
			<geometry>
				<sphere radius="1e-06" />
			</geometry>
		</collision>
	</link>
	<joint name="right_hand_ry" type="fixed">
		<parent link = "right_hand_rx" />
		<child link = "right_hand_ry" />
		<origin rpy = "0 0 0" xyz ="0 0 0"  />
	</joint>
	<link name = "right_hand_rz">
		<inertial>
			<origin rpy = "0 0 0"  xyz = "0 0 0" />
			<mass value =  "1e-05" />
			<inertia ixx = "0.1" ixy = "0" ixz = "0" iyy = "0.1" iyz = "0" izz = "0.1" />
		</inertial>
		<collision>
			<origin rpy = "0 0 0"  xyz = "0 0 0" />
			<geometry>
				<sphere radius="1e-05" />
			</geometry>
		</collision>
	</link>
	<joint name="right_hand_rz" type="fixed">
		<parent link = "right_hand_ry" />
		<child link = "right_hand_rz" />
		<origin rpy = "0 0 0" xyz ="0 0 0"  />
	</joint>
</robot>